[28/Aug/2020 21:42:41] ERROR [django.request:228] Internal Server Error: /subject_trainer/7/
Traceback (most recent call last):
  File "C:\Users\savek\Documents\spooner\project\pters-connect-venv\lib\site-packages\django\core\handlers\exception.py", line 34, in inner
    response = get_response(request)
  File "C:\Users\savek\Documents\spooner\project\pters-connect-venv\lib\site-packages\django\core\handlers\base.py", line 145, in _get_response
    response = self.process_exception_by_middleware(e, request)
  File "C:\Users\savek\Documents\spooner\project\pters-connect-venv\lib\site-packages\django\core\handlers\base.py", line 143, in _get_response
    response = response.render()
  File "C:\Users\savek\Documents\spooner\project\pters-connect-venv\lib\site-packages\django\template\response.py", line 105, in render
    self.content = self.rendered_content
  File "C:\Users\savek\Documents\spooner\project\pters-connect-venv\lib\site-packages\rest_framework\response.py", line 70, in rendered_content
    ret = renderer.render(self.data, accepted_media_type, context)
  File "C:\Users\savek\Documents\spooner\project\pters-connect-venv\lib\site-packages\rest_framework\renderers.py", line 724, in render
    context = self.get_context(data, accepted_media_type, renderer_context)
  File "C:\Users\savek\Documents\spooner\project\pters-connect-venv\lib\site-packages\rest_framework\renderers.py", line 656, in get_context
    raw_data_put_form = self.get_raw_data_form(data, view, 'PUT', request)
  File "C:\Users\savek\Documents\spooner\project\pters-connect-venv\lib\site-packages\rest_framework\renderers.py", line 563, in get_raw_data_form
    data = serializer.data.copy()
  File "C:\Users\savek\Documents\spooner\project\pters-connect-venv\lib\site-packages\rest_framework\serializers.py", line 562, in data
    ret = super().data
  File "C:\Users\savek\Documents\spooner\project\pters-connect-venv\lib\site-packages\rest_framework\serializers.py", line 260, in data
    self._data = self.to_representation(self.instance)
  File "C:\Users\savek\Documents\spooner\project\pters-connect-venv\lib\site-packages\rest_framework\serializers.py", line 514, in to_representation
    for field in fields:
  File "C:\Users\savek\Documents\spooner\project\pters-connect-venv\lib\site-packages\rest_framework\serializers.py", line 375, in _readable_fields
    for field in self.fields.values():
  File "C:\Users\savek\Documents\spooner\project\pters-connect-venv\lib\site-packages\django\utils\functional.py", line 48, in __get__
    res = instance.__dict__[self.name] = self.func(instance)
  File "C:\Users\savek\Documents\spooner\project\pters-connect-venv\lib\site-packages\rest_framework\serializers.py", line 363, in fields
    for key, value in self.get_fields().items():
  File "C:\Users\savek\Documents\spooner\project\pters-connect-venv\lib\site-packages\rest_framework\serializers.py", line 1038, in get_fields
    field_names = self.get_field_names(declared_fields, info)
  File "C:\Users\savek\Documents\spooner\project\pters-connect-venv\lib\site-packages\rest_framework\serializers.py", line 1139, in get_field_names
    serializer_class=self.__class__.__name__
AssertionError: The field 'member' was declared on serializer SubjectTrainerUpdateSerializer, but has not been included in the 'fields' option.
[28/Aug/2020 21:42:41] ERROR [django.server:157] "GET /subject_trainer/7/ HTTP/1.1" 500 156103
[28/Aug/2020 21:42:41] ERROR [django.server:157] "GET /subject_trainer/7/ HTTP/1.1" 500 156103
[28/Aug/2020 22:56:50] ERROR [django.request:228] Internal Server Error: /sms_auth/
Traceback (most recent call last):
  File "C:\Users\savek\Documents\spooner\project\pters-connect-venv\lib\site-packages\django\core\handlers\exception.py", line 34, in inner
    response = get_response(request)
  File "C:\Users\savek\Documents\spooner\project\pters-connect-venv\lib\site-packages\django\core\handlers\base.py", line 115, in _get_response
    response = self.process_exception_by_middleware(e, request)
  File "C:\Users\savek\Documents\spooner\project\pters-connect-venv\lib\site-packages\django\core\handlers\base.py", line 113, in _get_response
    response = wrapped_callback(request, *callback_args, **callback_kwargs)
  File "C:\Users\savek\Documents\spooner\project\pters-connect-venv\lib\site-packages\django\views\decorators\csrf.py", line 54, in wrapped_view
    return view_func(*args, **kwargs)
  File "C:\Users\savek\Documents\spooner\project\pters-connect-venv\lib\site-packages\django\views\generic\base.py", line 71, in view
    return self.dispatch(request, *args, **kwargs)
  File "C:\Users\savek\Documents\spooner\project\pters-connect-venv\lib\site-packages\rest_framework\views.py", line 505, in dispatch
    response = self.handle_exception(exc)
  File "C:\Users\savek\Documents\spooner\project\pters-connect-venv\lib\site-packages\rest_framework\views.py", line 465, in handle_exception
    self.raise_uncaught_exception(exc)
  File "C:\Users\savek\Documents\spooner\project\pters-connect-venv\lib\site-packages\rest_framework\views.py", line 476, in raise_uncaught_exception
    raise exc
  File "C:\Users\savek\Documents\spooner\project\pters-connect-venv\lib\site-packages\rest_framework\views.py", line 502, in dispatch
    response = handler(request, *args, **kwargs)
  File "C:\Users\savek\Documents\spooner\project\pters-connect\pters_connect\api\account\views.py", line 21, in post
    request.data['auth_check'] = False
  File "C:\Users\savek\Documents\spooner\project\pters-connect-venv\lib\site-packages\django\http\request.py", line 467, in __setitem__
    self._assert_mutable()
  File "C:\Users\savek\Documents\spooner\project\pters-connect-venv\lib\site-packages\django\http\request.py", line 464, in _assert_mutable
    raise AttributeError("This QueryDict instance is immutable")
AttributeError: This QueryDict instance is immutable
[28/Aug/2020 22:56:50] ERROR [django.server:157] "POST /sms_auth/ HTTP/1.1" 500 25939
[28/Aug/2020 22:56:50] ERROR [django.server:157] "POST /sms_auth/ HTTP/1.1" 500 25939
[28/Aug/2020 22:57:33] ERROR [django.request:228] Internal Server Error: /sms_auth/
Traceback (most recent call last):
  File "C:\Users\savek\Documents\spooner\project\pters-connect-venv\lib\site-packages\django\core\handlers\exception.py", line 34, in inner
    response = get_response(request)
  File "C:\Users\savek\Documents\spooner\project\pters-connect-venv\lib\site-packages\django\core\handlers\base.py", line 115, in _get_response
    response = self.process_exception_by_middleware(e, request)
  File "C:\Users\savek\Documents\spooner\project\pters-connect-venv\lib\site-packages\django\core\handlers\base.py", line 113, in _get_response
    response = wrapped_callback(request, *callback_args, **callback_kwargs)
  File "C:\Users\savek\Documents\spooner\project\pters-connect-venv\lib\site-packages\django\views\decorators\csrf.py", line 54, in wrapped_view
    return view_func(*args, **kwargs)
  File "C:\Users\savek\Documents\spooner\project\pters-connect-venv\lib\site-packages\django\views\generic\base.py", line 71, in view
    return self.dispatch(request, *args, **kwargs)
  File "C:\Users\savek\Documents\spooner\project\pters-connect-venv\lib\site-packages\rest_framework\views.py", line 505, in dispatch
    response = self.handle_exception(exc)
  File "C:\Users\savek\Documents\spooner\project\pters-connect-venv\lib\site-packages\rest_framework\views.py", line 465, in handle_exception
    self.raise_uncaught_exception(exc)
  File "C:\Users\savek\Documents\spooner\project\pters-connect-venv\lib\site-packages\rest_framework\views.py", line 476, in raise_uncaught_exception
    raise exc
  File "C:\Users\savek\Documents\spooner\project\pters-connect-venv\lib\site-packages\rest_framework\views.py", line 502, in dispatch
    response = handler(request, *args, **kwargs)
  File "C:\Users\savek\Documents\spooner\project\pters-connect\pters_connect\api\account\views.py", line 23, in post
    request.data['auth_check'] = False
  File "C:\Users\savek\Documents\spooner\project\pters-connect-venv\lib\site-packages\django\http\request.py", line 467, in __setitem__
    self._assert_mutable()
  File "C:\Users\savek\Documents\spooner\project\pters-connect-venv\lib\site-packages\django\http\request.py", line 464, in _assert_mutable
    raise AttributeError("This QueryDict instance is immutable")
AttributeError: This QueryDict instance is immutable
[28/Aug/2020 22:57:33] ERROR [django.server:157] "POST /sms_auth/ HTTP/1.1" 500 25939
[28/Aug/2020 22:57:33] ERROR [django.server:157] "POST /sms_auth/ HTTP/1.1" 500 25939
[28/Aug/2020 22:58:10] ERROR [django.request:228] Internal Server Error: /sms_auth/
Traceback (most recent call last):
  File "C:\Users\savek\Documents\spooner\project\pters-connect-venv\lib\site-packages\django\core\handlers\exception.py", line 34, in inner
    response = get_response(request)
  File "C:\Users\savek\Documents\spooner\project\pters-connect-venv\lib\site-packages\django\core\handlers\base.py", line 115, in _get_response
    response = self.process_exception_by_middleware(e, request)
  File "C:\Users\savek\Documents\spooner\project\pters-connect-venv\lib\site-packages\django\core\handlers\base.py", line 113, in _get_response
    response = wrapped_callback(request, *callback_args, **callback_kwargs)
  File "C:\Users\savek\Documents\spooner\project\pters-connect-venv\lib\site-packages\django\views\decorators\csrf.py", line 54, in wrapped_view
    return view_func(*args, **kwargs)
  File "C:\Users\savek\Documents\spooner\project\pters-connect-venv\lib\site-packages\django\views\generic\base.py", line 71, in view
    return self.dispatch(request, *args, **kwargs)
  File "C:\Users\savek\Documents\spooner\project\pters-connect-venv\lib\site-packages\rest_framework\views.py", line 505, in dispatch
    response = self.handle_exception(exc)
  File "C:\Users\savek\Documents\spooner\project\pters-connect-venv\lib\site-packages\rest_framework\views.py", line 465, in handle_exception
    self.raise_uncaught_exception(exc)
  File "C:\Users\savek\Documents\spooner\project\pters-connect-venv\lib\site-packages\rest_framework\views.py", line 476, in raise_uncaught_exception
    raise exc
  File "C:\Users\savek\Documents\spooner\project\pters-connect-venv\lib\site-packages\rest_framework\views.py", line 502, in dispatch
    response = handler(request, *args, **kwargs)
  File "C:\Users\savek\Documents\spooner\project\pters-connect\pters_connect\api\account\views.py", line 23, in post
    request.data['auth_check'] = False
  File "C:\Users\savek\Documents\spooner\project\pters-connect-venv\lib\site-packages\django\http\request.py", line 467, in __setitem__
    self._assert_mutable()
  File "C:\Users\savek\Documents\spooner\project\pters-connect-venv\lib\site-packages\django\http\request.py", line 464, in _assert_mutable
    raise AttributeError("This QueryDict instance is immutable")
AttributeError: This QueryDict instance is immutable
[28/Aug/2020 22:58:10] ERROR [django.server:157] "POST /sms_auth/ HTTP/1.1" 500 25939
[28/Aug/2020 22:58:10] ERROR [django.server:157] "POST /sms_auth/ HTTP/1.1" 500 25939
[28/Aug/2020 22:58:27] ERROR [django.request:228] Internal Server Error: /sms_auth/
Traceback (most recent call last):
  File "C:\Users\savek\Documents\spooner\project\pters-connect-venv\lib\site-packages\django\core\handlers\exception.py", line 34, in inner
    response = get_response(request)
  File "C:\Users\savek\Documents\spooner\project\pters-connect-venv\lib\site-packages\django\core\handlers\base.py", line 115, in _get_response
    response = self.process_exception_by_middleware(e, request)
  File "C:\Users\savek\Documents\spooner\project\pters-connect-venv\lib\site-packages\django\core\handlers\base.py", line 113, in _get_response
    response = wrapped_callback(request, *callback_args, **callback_kwargs)
  File "C:\Users\savek\Documents\spooner\project\pters-connect-venv\lib\site-packages\django\views\decorators\csrf.py", line 54, in wrapped_view
    return view_func(*args, **kwargs)
  File "C:\Users\savek\Documents\spooner\project\pters-connect-venv\lib\site-packages\django\views\generic\base.py", line 71, in view
    return self.dispatch(request, *args, **kwargs)
  File "C:\Users\savek\Documents\spooner\project\pters-connect-venv\lib\site-packages\rest_framework\views.py", line 505, in dispatch
    response = self.handle_exception(exc)
  File "C:\Users\savek\Documents\spooner\project\pters-connect-venv\lib\site-packages\rest_framework\views.py", line 465, in handle_exception
    self.raise_uncaught_exception(exc)
  File "C:\Users\savek\Documents\spooner\project\pters-connect-venv\lib\site-packages\rest_framework\views.py", line 476, in raise_uncaught_exception
    raise exc
  File "C:\Users\savek\Documents\spooner\project\pters-connect-venv\lib\site-packages\rest_framework\views.py", line 502, in dispatch
    response = handler(request, *args, **kwargs)
  File "C:\Users\savek\Documents\spooner\project\pters-connect\pters_connect\api\account\views.py", line 23, in post
    request.data['auth_check'] = False
  File "C:\Users\savek\Documents\spooner\project\pters-connect-venv\lib\site-packages\django\http\request.py", line 467, in __setitem__
    self._assert_mutable()
  File "C:\Users\savek\Documents\spooner\project\pters-connect-venv\lib\site-packages\django\http\request.py", line 464, in _assert_mutable
    raise AttributeError("This QueryDict instance is immutable")
AttributeError: This QueryDict instance is immutable
[28/Aug/2020 22:58:27] ERROR [django.server:157] "POST /sms_auth/ HTTP/1.1" 500 25939
[28/Aug/2020 22:58:27] ERROR [django.server:157] "POST /sms_auth/ HTTP/1.1" 500 25939
[28/Aug/2020 23:01:47] ERROR [django.request:228] Internal Server Error: /sms_auth/
Traceback (most recent call last):
  File "C:\Users\savek\Documents\spooner\project\pters-connect-venv\lib\site-packages\django\db\backends\utils.py", line 86, in _execute
    return self.cursor.execute(sql, params)
  File "C:\Users\savek\Documents\spooner\project\pters-connect-venv\lib\site-packages\django\db\backends\mysql\base.py", line 74, in execute
    return self.cursor.execute(query, args)
  File "C:\Users\savek\Documents\spooner\project\pters-connect-venv\lib\site-packages\pymysql\cursors.py", line 163, in execute
    result = self._query(query)
  File "C:\Users\savek\Documents\spooner\project\pters-connect-venv\lib\site-packages\pymysql\cursors.py", line 321, in _query
    conn.query(q)
  File "C:\Users\savek\Documents\spooner\project\pters-connect-venv\lib\site-packages\pymysql\connections.py", line 505, in query
    self._affected_rows = self._read_query_result(unbuffered=unbuffered)
  File "C:\Users\savek\Documents\spooner\project\pters-connect-venv\lib\site-packages\pymysql\connections.py", line 724, in _read_query_result
    result.read()
  File "C:\Users\savek\Documents\spooner\project\pters-connect-venv\lib\site-packages\pymysql\connections.py", line 1069, in read
    first_packet = self.connection._read_packet()
  File "C:\Users\savek\Documents\spooner\project\pters-connect-venv\lib\site-packages\pymysql\connections.py", line 676, in _read_packet
    packet.raise_for_error()
  File "C:\Users\savek\Documents\spooner\project\pters-connect-venv\lib\site-packages\pymysql\protocol.py", line 223, in raise_for_error
    err.raise_mysql_exception(self._data)
  File "C:\Users\savek\Documents\spooner\project\pters-connect-venv\lib\site-packages\pymysql\err.py", line 107, in raise_mysql_exception
    raise errorclass(errno, errval)
pymysql.err.ProgrammingError: (1146, "Table 'pters-test.SMS_AUTH_TB' doesn't exist")

The above exception was the direct cause of the following exception:

Traceback (most recent call last):
  File "C:\Users\savek\Documents\spooner\project\pters-connect-venv\lib\site-packages\django\core\handlers\exception.py", line 34, in inner
    response = get_response(request)
  File "C:\Users\savek\Documents\spooner\project\pters-connect-venv\lib\site-packages\django\core\handlers\base.py", line 115, in _get_response
    response = self.process_exception_by_middleware(e, request)
  File "C:\Users\savek\Documents\spooner\project\pters-connect-venv\lib\site-packages\django\core\handlers\base.py", line 113, in _get_response
    response = wrapped_callback(request, *callback_args, **callback_kwargs)
  File "C:\Users\savek\Documents\spooner\project\pters-connect-venv\lib\site-packages\django\views\decorators\csrf.py", line 54, in wrapped_view
    return view_func(*args, **kwargs)
  File "C:\Users\savek\Documents\spooner\project\pters-connect-venv\lib\site-packages\django\views\generic\base.py", line 71, in view
    return self.dispatch(request, *args, **kwargs)
  File "C:\Users\savek\Documents\spooner\project\pters-connect-venv\lib\site-packages\rest_framework\views.py", line 505, in dispatch
    response = self.handle_exception(exc)
  File "C:\Users\savek\Documents\spooner\project\pters-connect-venv\lib\site-packages\rest_framework\views.py", line 465, in handle_exception
    self.raise_uncaught_exception(exc)
  File "C:\Users\savek\Documents\spooner\project\pters-connect-venv\lib\site-packages\rest_framework\views.py", line 476, in raise_uncaught_exception
    raise exc
  File "C:\Users\savek\Documents\spooner\project\pters-connect-venv\lib\site-packages\rest_framework\views.py", line 502, in dispatch
    response = handler(request, *args, **kwargs)
  File "C:\Users\savek\Documents\spooner\project\pters-connect\pters_connect\api\account\views.py", line 31, in post
    serializer.save()
  File "C:\Users\savek\Documents\spooner\project\pters-connect-venv\lib\site-packages\rest_framework\serializers.py", line 212, in save
    self.instance = self.create(validated_data)
  File "C:\Users\savek\Documents\spooner\project\pters-connect-venv\lib\site-packages\rest_framework\serializers.py", line 948, in create
    instance = ModelClass._default_manager.create(**validated_data)
  File "C:\Users\savek\Documents\spooner\project\pters-connect-venv\lib\site-packages\django\db\models\manager.py", line 82, in manager_method
    return getattr(self.get_queryset(), name)(*args, **kwargs)
  File "C:\Users\savek\Documents\spooner\project\pters-connect-venv\lib\site-packages\django\db\models\query.py", line 433, in create
    obj.save(force_insert=True, using=self.db)
  File "C:\Users\savek\Documents\spooner\project\pters-connect-venv\lib\site-packages\django\db\models\base.py", line 746, in save
    force_update=force_update, update_fields=update_fields)
  File "C:\Users\savek\Documents\spooner\project\pters-connect-venv\lib\site-packages\django\db\models\base.py", line 784, in save_base
    force_update, using, update_fields,
  File "C:\Users\savek\Documents\spooner\project\pters-connect-venv\lib\site-packages\django\db\models\base.py", line 886, in _save_table
    results = self._do_insert(cls._base_manager, using, fields, returning_fields, raw)
  File "C:\Users\savek\Documents\spooner\project\pters-connect-venv\lib\site-packages\django\db\models\base.py", line 925, in _do_insert
    using=using, raw=raw,
  File "C:\Users\savek\Documents\spooner\project\pters-connect-venv\lib\site-packages\django\db\models\manager.py", line 82, in manager_method
    return getattr(self.get_queryset(), name)(*args, **kwargs)
  File "C:\Users\savek\Documents\spooner\project\pters-connect-venv\lib\site-packages\django\db\models\query.py", line 1204, in _insert
    return query.get_compiler(using=using).execute_sql(returning_fields)
  File "C:\Users\savek\Documents\spooner\project\pters-connect-venv\lib\site-packages\django\db\models\sql\compiler.py", line 1377, in execute_sql
    cursor.execute(sql, params)
  File "C:\Users\savek\Documents\spooner\project\pters-connect-venv\lib\site-packages\django\db\backends\utils.py", line 100, in execute
    return super().execute(sql, params)
  File "C:\Users\savek\Documents\spooner\project\pters-connect-venv\lib\site-packages\django\db\backends\utils.py", line 68, in execute
    return self._execute_with_wrappers(sql, params, many=False, executor=self._execute)
  File "C:\Users\savek\Documents\spooner\project\pters-connect-venv\lib\site-packages\django\db\backends\utils.py", line 77, in _execute_with_wrappers
    return executor(sql, params, many, context)
  File "C:\Users\savek\Documents\spooner\project\pters-connect-venv\lib\site-packages\django\db\backends\utils.py", line 86, in _execute
    return self.cursor.execute(sql, params)
  File "C:\Users\savek\Documents\spooner\project\pters-connect-venv\lib\site-packages\django\db\utils.py", line 90, in __exit__
    raise dj_exc_value.with_traceback(traceback) from exc_value
  File "C:\Users\savek\Documents\spooner\project\pters-connect-venv\lib\site-packages\django\db\backends\utils.py", line 86, in _execute
    return self.cursor.execute(sql, params)
  File "C:\Users\savek\Documents\spooner\project\pters-connect-venv\lib\site-packages\django\db\backends\mysql\base.py", line 74, in execute
    return self.cursor.execute(query, args)
  File "C:\Users\savek\Documents\spooner\project\pters-connect-venv\lib\site-packages\pymysql\cursors.py", line 163, in execute
    result = self._query(query)
  File "C:\Users\savek\Documents\spooner\project\pters-connect-venv\lib\site-packages\pymysql\cursors.py", line 321, in _query
    conn.query(q)
  File "C:\Users\savek\Documents\spooner\project\pters-connect-venv\lib\site-packages\pymysql\connections.py", line 505, in query
    self._affected_rows = self._read_query_result(unbuffered=unbuffered)
  File "C:\Users\savek\Documents\spooner\project\pters-connect-venv\lib\site-packages\pymysql\connections.py", line 724, in _read_query_result
    result.read()
  File "C:\Users\savek\Documents\spooner\project\pters-connect-venv\lib\site-packages\pymysql\connections.py", line 1069, in read
    first_packet = self.connection._read_packet()
  File "C:\Users\savek\Documents\spooner\project\pters-connect-venv\lib\site-packages\pymysql\connections.py", line 676, in _read_packet
    packet.raise_for_error()
  File "C:\Users\savek\Documents\spooner\project\pters-connect-venv\lib\site-packages\pymysql\protocol.py", line 223, in raise_for_error
    err.raise_mysql_exception(self._data)
  File "C:\Users\savek\Documents\spooner\project\pters-connect-venv\lib\site-packages\pymysql\err.py", line 107, in raise_mysql_exception
    raise errorclass(errno, errval)
django.db.utils.ProgrammingError: (1146, "Table 'pters-test.SMS_AUTH_TB' doesn't exist")
[28/Aug/2020 23:01:47] ERROR [django.server:157] "POST /sms_auth/ HTTP/1.1" 500 32288
[28/Aug/2020 23:01:47] ERROR [django.server:157] "POST /sms_auth/ HTTP/1.1" 500 32288
[28/Aug/2020 23:06:49] ERROR [django.request:228] Internal Server Error: /sms_auth_check/
Traceback (most recent call last):
  File "C:\Users\savek\Documents\spooner\project\pters-connect-venv\lib\site-packages\django\core\handlers\exception.py", line 34, in inner
    response = get_response(request)
  File "C:\Users\savek\Documents\spooner\project\pters-connect-venv\lib\site-packages\django\core\handlers\base.py", line 115, in _get_response
    response = self.process_exception_by_middleware(e, request)
  File "C:\Users\savek\Documents\spooner\project\pters-connect-venv\lib\site-packages\django\core\handlers\base.py", line 113, in _get_response
    response = wrapped_callback(request, *callback_args, **callback_kwargs)
  File "C:\Users\savek\Documents\spooner\project\pters-connect-venv\lib\site-packages\django\views\decorators\csrf.py", line 54, in wrapped_view
    return view_func(*args, **kwargs)
  File "C:\Users\savek\Documents\spooner\project\pters-connect-venv\lib\site-packages\django\views\generic\base.py", line 71, in view
    return self.dispatch(request, *args, **kwargs)
  File "C:\Users\savek\Documents\spooner\project\pters-connect-venv\lib\site-packages\rest_framework\views.py", line 505, in dispatch
    response = self.handle_exception(exc)
  File "C:\Users\savek\Documents\spooner\project\pters-connect-venv\lib\site-packages\rest_framework\views.py", line 465, in handle_exception
    self.raise_uncaught_exception(exc)
  File "C:\Users\savek\Documents\spooner\project\pters-connect-venv\lib\site-packages\rest_framework\views.py", line 476, in raise_uncaught_exception
    raise exc
  File "C:\Users\savek\Documents\spooner\project\pters-connect-venv\lib\site-packages\rest_framework\views.py", line 502, in dispatch
    response = handler(request, *args, **kwargs)
  File "C:\Users\savek\Documents\spooner\project\pters-connect\pters_connect\api\account\views.py", line 41, in post
    sms_auth_info = self.get_object(phone_number=request.data['phone_number'])
AttributeError: 'SmsAuthCheckAPIView' object has no attribute 'get_object'
[28/Aug/2020 23:06:49] ERROR [django.server:157] "POST /sms_auth_check/ HTTP/1.1" 500 25640
[28/Aug/2020 23:06:49] ERROR [django.server:157] "POST /sms_auth_check/ HTTP/1.1" 500 25640
[28/Aug/2020 23:13:39] ERROR [django.request:228] Internal Server Error: /sms_auth_check/
Traceback (most recent call last):
  File "C:\Users\savek\Documents\spooner\project\pters-connect-venv\lib\site-packages\django\core\handlers\exception.py", line 34, in inner
    response = get_response(request)
  File "C:\Users\savek\Documents\spooner\project\pters-connect-venv\lib\site-packages\django\core\handlers\base.py", line 115, in _get_response
    response = self.process_exception_by_middleware(e, request)
  File "C:\Users\savek\Documents\spooner\project\pters-connect-venv\lib\site-packages\django\core\handlers\base.py", line 113, in _get_response
    response = wrapped_callback(request, *callback_args, **callback_kwargs)
  File "C:\Users\savek\Documents\spooner\project\pters-connect-venv\lib\site-packages\django\views\decorators\csrf.py", line 54, in wrapped_view
    return view_func(*args, **kwargs)
  File "C:\Users\savek\Documents\spooner\project\pters-connect-venv\lib\site-packages\django\views\generic\base.py", line 71, in view
    return self.dispatch(request, *args, **kwargs)
  File "C:\Users\savek\Documents\spooner\project\pters-connect-venv\lib\site-packages\rest_framework\views.py", line 505, in dispatch
    response = self.handle_exception(exc)
  File "C:\Users\savek\Documents\spooner\project\pters-connect-venv\lib\site-packages\rest_framework\views.py", line 465, in handle_exception
    self.raise_uncaught_exception(exc)
  File "C:\Users\savek\Documents\spooner\project\pters-connect-venv\lib\site-packages\rest_framework\views.py", line 476, in raise_uncaught_exception
    raise exc
  File "C:\Users\savek\Documents\spooner\project\pters-connect-venv\lib\site-packages\rest_framework\views.py", line 502, in dispatch
    response = handler(request, *args, **kwargs)
  File "C:\Users\savek\Documents\spooner\project\pters-connect\pters_connect\api\account\views.py", line 57, in post
    if time_interval > settings.SMS_ACTIVATION_SECONDS:
TypeError: '>' not supported between instances of 'datetime.timedelta' and 'int'
[28/Aug/2020 23:13:39] ERROR [django.server:157] "POST /sms_auth_check/ HTTP/1.1" 500 25629
[28/Aug/2020 23:13:39] ERROR [django.server:157] "POST /sms_auth_check/ HTTP/1.1" 500 25629
[28/Aug/2020 23:14:19] ERROR [django.request:228] Internal Server Error: /sms_auth_check/
Traceback (most recent call last):
  File "C:\Users\savek\Documents\spooner\project\pters-connect-venv\lib\site-packages\django\core\handlers\exception.py", line 34, in inner
    response = get_response(request)
  File "C:\Users\savek\Documents\spooner\project\pters-connect-venv\lib\site-packages\django\core\handlers\base.py", line 115, in _get_response
    response = self.process_exception_by_middleware(e, request)
  File "C:\Users\savek\Documents\spooner\project\pters-connect-venv\lib\site-packages\django\core\handlers\base.py", line 113, in _get_response
    response = wrapped_callback(request, *callback_args, **callback_kwargs)
  File "C:\Users\savek\Documents\spooner\project\pters-connect-venv\lib\site-packages\django\views\decorators\csrf.py", line 54, in wrapped_view
    return view_func(*args, **kwargs)
  File "C:\Users\savek\Documents\spooner\project\pters-connect-venv\lib\site-packages\django\views\generic\base.py", line 71, in view
    return self.dispatch(request, *args, **kwargs)
  File "C:\Users\savek\Documents\spooner\project\pters-connect-venv\lib\site-packages\rest_framework\views.py", line 505, in dispatch
    response = self.handle_exception(exc)
  File "C:\Users\savek\Documents\spooner\project\pters-connect-venv\lib\site-packages\rest_framework\views.py", line 465, in handle_exception
    self.raise_uncaught_exception(exc)
  File "C:\Users\savek\Documents\spooner\project\pters-connect-venv\lib\site-packages\rest_framework\views.py", line 476, in raise_uncaught_exception
    raise exc
  File "C:\Users\savek\Documents\spooner\project\pters-connect-venv\lib\site-packages\rest_framework\views.py", line 502, in dispatch
    response = handler(request, *args, **kwargs)
  File "C:\Users\savek\Documents\spooner\project\pters-connect\pters_connect\api\account\views.py", line 57, in post
    if time_interval > settings.SMS_ACTIVATION_SECONDS:
TypeError: '>' not supported between instances of 'datetime.timedelta' and 'int'
[28/Aug/2020 23:14:19] ERROR [django.server:157] "POST /sms_auth_check/ HTTP/1.1" 500 25629
[28/Aug/2020 23:14:19] ERROR [django.server:157] "POST /sms_auth_check/ HTTP/1.1" 500 25629
[28/Aug/2020 23:30:33] ERROR [django.request:228] Internal Server Error: /sms_auth_check/
Traceback (most recent call last):
  File "C:\Users\savek\Documents\spooner\project\pters-connect-venv\lib\site-packages\django\core\handlers\exception.py", line 34, in inner
    response = get_response(request)
  File "C:\Users\savek\Documents\spooner\project\pters-connect-venv\lib\site-packages\django\core\handlers\base.py", line 115, in _get_response
    response = self.process_exception_by_middleware(e, request)
  File "C:\Users\savek\Documents\spooner\project\pters-connect-venv\lib\site-packages\django\core\handlers\base.py", line 113, in _get_response
    response = wrapped_callback(request, *callback_args, **callback_kwargs)
  File "C:\Users\savek\Documents\spooner\project\pters-connect-venv\lib\site-packages\django\views\decorators\csrf.py", line 54, in wrapped_view
    return view_func(*args, **kwargs)
  File "C:\Users\savek\Documents\spooner\project\pters-connect-venv\lib\site-packages\django\views\generic\base.py", line 71, in view
    return self.dispatch(request, *args, **kwargs)
  File "C:\Users\savek\Documents\spooner\project\pters-connect-venv\lib\site-packages\rest_framework\views.py", line 505, in dispatch
    response = self.handle_exception(exc)
  File "C:\Users\savek\Documents\spooner\project\pters-connect-venv\lib\site-packages\rest_framework\views.py", line 465, in handle_exception
    self.raise_uncaught_exception(exc)
  File "C:\Users\savek\Documents\spooner\project\pters-connect-venv\lib\site-packages\rest_framework\views.py", line 476, in raise_uncaught_exception
    raise exc
  File "C:\Users\savek\Documents\spooner\project\pters-connect-venv\lib\site-packages\rest_framework\views.py", line 502, in dispatch
    response = handler(request, *args, **kwargs)
  File "C:\Users\savek\Documents\spooner\project\pters-connect\pters_connect\api\account\views.py", line 47, in post
    sms_auth_info = SmsAuthTb.objects.filter(phone_number=request.data['phone_number']).latest()
  File "C:\Users\savek\Documents\spooner\project\pters-connect-venv\lib\site-packages\django\db\models\query.py", line 660, in latest
    return self.reverse()._earliest(*fields)
  File "C:\Users\savek\Documents\spooner\project\pters-connect-venv\lib\site-packages\django\db\models\query.py", line 644, in _earliest
    "earliest() and latest() require either fields as positional "
ValueError: earliest() and latest() require either fields as positional arguments or 'get_latest_by' in the model's Meta.
[28/Aug/2020 23:30:33] ERROR [django.server:157] "POST /sms_auth_check/ HTTP/1.1" 500 26135
[28/Aug/2020 23:30:33] ERROR [django.server:157] "POST /sms_auth_check/ HTTP/1.1" 500 26135
[30/Aug/2020 01:50:39] ERROR [django.request:228] Internal Server Error: /member/5/add_social_info
Traceback (most recent call last):
  File "C:\Users\savek\Documents\spooner\project\pters-connect-venv\lib\site-packages\django\core\handlers\exception.py", line 34, in inner
    response = get_response(request)
  File "C:\Users\savek\Documents\spooner\project\pters-connect-venv\lib\site-packages\django\utils\deprecation.py", line 93, in __call__
    response = self.process_request(request)
  File "C:\Users\savek\Documents\spooner\project\pters-connect-venv\lib\site-packages\django\middleware\common.py", line 54, in process_request
    path = self.get_full_path_with_slash(request)
  File "C:\Users\savek\Documents\spooner\project\pters-connect-venv\lib\site-packages\django\middleware\common.py", line 94, in get_full_path_with_slash
    'url': request.get_host() + new_path,
RuntimeError: You called this URL via POST, but the URL doesn't end in a slash and you have APPEND_SLASH set. Django can't redirect to the slash URL while maintaining POST data. Change your form to point to localhost:8080/member/5/add_social_info/ (note the trailing slash), or set APPEND_SLASH=False in your Django settings.
[30/Aug/2020 01:50:39] ERROR [django.server:157] "POST /member/5/add_social_info HTTP/1.1" 500 87719
[30/Aug/2020 01:50:39] ERROR [django.server:157] "POST /member/5/add_social_info HTTP/1.1" 500 87719
[30/Aug/2020 01:51:27] ERROR [django.request:228] Internal Server Error: /member/5/add_social_info
Traceback (most recent call last):
  File "C:\Users\savek\Documents\spooner\project\pters-connect-venv\lib\site-packages\django\core\handlers\exception.py", line 34, in inner
    response = get_response(request)
  File "C:\Users\savek\Documents\spooner\project\pters-connect-venv\lib\site-packages\django\utils\deprecation.py", line 93, in __call__
    response = self.process_request(request)
  File "C:\Users\savek\Documents\spooner\project\pters-connect-venv\lib\site-packages\django\middleware\common.py", line 54, in process_request
    path = self.get_full_path_with_slash(request)
  File "C:\Users\savek\Documents\spooner\project\pters-connect-venv\lib\site-packages\django\middleware\common.py", line 94, in get_full_path_with_slash
    'url': request.get_host() + new_path,
RuntimeError: You called this URL via POST, but the URL doesn't end in a slash and you have APPEND_SLASH set. Django can't redirect to the slash URL while maintaining POST data. Change your form to point to localhost:8080/member/5/add_social_info/ (note the trailing slash), or set APPEND_SLASH=False in your Django settings.
[30/Aug/2020 01:51:27] ERROR [django.server:157] "POST /member/5/add_social_info HTTP/1.1" 500 87757
[30/Aug/2020 01:52:05] ERROR [django.request:228] Internal Server Error: /member/5/add_social_info
Traceback (most recent call last):
  File "C:\Users\savek\Documents\spooner\project\pters-connect-venv\lib\site-packages\django\core\handlers\exception.py", line 34, in inner
    response = get_response(request)
  File "C:\Users\savek\Documents\spooner\project\pters-connect-venv\lib\site-packages\django\utils\deprecation.py", line 93, in __call__
    response = self.process_request(request)
  File "C:\Users\savek\Documents\spooner\project\pters-connect-venv\lib\site-packages\django\middleware\common.py", line 54, in process_request
    path = self.get_full_path_with_slash(request)
  File "C:\Users\savek\Documents\spooner\project\pters-connect-venv\lib\site-packages\django\middleware\common.py", line 94, in get_full_path_with_slash
    'url': request.get_host() + new_path,
RuntimeError: You called this URL via POST, but the URL doesn't end in a slash and you have APPEND_SLASH set. Django can't redirect to the slash URL while maintaining POST data. Change your form to point to localhost:8080/member/5/add_social_info/ (note the trailing slash), or set APPEND_SLASH=False in your Django settings.
[30/Aug/2020 01:52:05] ERROR [django.server:157] "POST /member/5/add_social_info HTTP/1.1" 500 87757
[30/Aug/2020 01:53:23] ERROR [django.request:228] Internal Server Error: /member/5/add_social_info/
Traceback (most recent call last):
  File "C:\Users\savek\Documents\spooner\project\pters-connect-venv\lib\site-packages\django\core\handlers\exception.py", line 34, in inner
    response = get_response(request)
  File "C:\Users\savek\Documents\spooner\project\pters-connect-venv\lib\site-packages\django\core\handlers\base.py", line 115, in _get_response
    response = self.process_exception_by_middleware(e, request)
  File "C:\Users\savek\Documents\spooner\project\pters-connect-venv\lib\site-packages\django\core\handlers\base.py", line 113, in _get_response
    response = wrapped_callback(request, *callback_args, **callback_kwargs)
  File "C:\Users\savek\Documents\spooner\project\pters-connect-venv\lib\site-packages\django\views\decorators\csrf.py", line 54, in wrapped_view
    return view_func(*args, **kwargs)
  File "C:\Users\savek\Documents\spooner\project\pters-connect-venv\lib\site-packages\rest_framework\viewsets.py", line 114, in view
    return self.dispatch(request, *args, **kwargs)
  File "C:\Users\savek\Documents\spooner\project\pters-connect-venv\lib\site-packages\rest_framework\views.py", line 505, in dispatch
    response = self.handle_exception(exc)
  File "C:\Users\savek\Documents\spooner\project\pters-connect-venv\lib\site-packages\rest_framework\views.py", line 465, in handle_exception
    self.raise_uncaught_exception(exc)
  File "C:\Users\savek\Documents\spooner\project\pters-connect-venv\lib\site-packages\rest_framework\views.py", line 476, in raise_uncaught_exception
    raise exc
  File "C:\Users\savek\Documents\spooner\project\pters-connect-venv\lib\site-packages\rest_framework\views.py", line 502, in dispatch
    response = handler(request, *args, **kwargs)
  File "C:\Users\savek\Documents\spooner\project\pters-connect\pters_connect\api\member\viewsets.py", line 52, in add_social_info
    request_data['member_id'] = member_info.member_id
  File "C:\Users\savek\Documents\spooner\project\pters-connect-venv\lib\site-packages\django\http\request.py", line 467, in __setitem__
    self._assert_mutable()
  File "C:\Users\savek\Documents\spooner\project\pters-connect-venv\lib\site-packages\django\http\request.py", line 464, in _assert_mutable
    raise AttributeError("This QueryDict instance is immutable")
AttributeError: This QueryDict instance is immutable
[30/Aug/2020 01:53:23] ERROR [django.server:157] "POST /member/5/add_social_info/ HTTP/1.1" 500 26442
[30/Aug/2020 02:15:21] ERROR [django.request:228] Internal Server Error: /facility/2/with_subjects/
Traceback (most recent call last):
  File "C:\Users\savek\Documents\spooner\project\pters-connect-venv\lib\site-packages\django\core\handlers\exception.py", line 34, in inner
    response = get_response(request)
  File "C:\Users\savek\Documents\spooner\project\pters-connect-venv\lib\site-packages\django\core\handlers\base.py", line 115, in _get_response
    response = self.process_exception_by_middleware(e, request)
  File "C:\Users\savek\Documents\spooner\project\pters-connect-venv\lib\site-packages\django\core\handlers\base.py", line 113, in _get_response
    response = wrapped_callback(request, *callback_args, **callback_kwargs)
  File "C:\Users\savek\Documents\spooner\project\pters-connect-venv\lib\site-packages\django\views\decorators\csrf.py", line 54, in wrapped_view
    return view_func(*args, **kwargs)
  File "C:\Users\savek\Documents\spooner\project\pters-connect-venv\lib\site-packages\rest_framework\viewsets.py", line 114, in view
    return self.dispatch(request, *args, **kwargs)
  File "C:\Users\savek\Documents\spooner\project\pters-connect-venv\lib\site-packages\rest_framework\views.py", line 505, in dispatch
    response = self.handle_exception(exc)
  File "C:\Users\savek\Documents\spooner\project\pters-connect-venv\lib\site-packages\rest_framework\views.py", line 465, in handle_exception
    self.raise_uncaught_exception(exc)
  File "C:\Users\savek\Documents\spooner\project\pters-connect-venv\lib\site-packages\rest_framework\views.py", line 476, in raise_uncaught_exception
    raise exc
  File "C:\Users\savek\Documents\spooner\project\pters-connect-venv\lib\site-packages\rest_framework\views.py", line 502, in dispatch
    response = handler(request, *args, **kwargs)
  File "C:\Users\savek\Documents\spooner\project\pters-connect\pters_connect\api\facility\viewsets.py", line 46, in with_subjects
    return Response(data=serializer.data)
  File "C:\Users\savek\Documents\spooner\project\pters-connect-venv\lib\site-packages\rest_framework\serializers.py", line 562, in data
    ret = super().data
  File "C:\Users\savek\Documents\spooner\project\pters-connect-venv\lib\site-packages\rest_framework\serializers.py", line 256, in data
    raise AssertionError(msg)
AssertionError: When a serializer is passed a `data` keyword argument you must call `.is_valid()` before attempting to access the serialized `.data` representation.
You should either call `.is_valid()` first, or access `.initial_data` instead.
[30/Aug/2020 02:15:21] ERROR [django.server:157] "GET /facility/2/with_subjects/ HTTP/1.1" 500 26948
[30/Aug/2020 02:17:03] ERROR [django.request:228] Internal Server Error: /facility/2/with_subjects/
Traceback (most recent call last):
  File "C:\Users\savek\Documents\spooner\project\pters-connect-venv\lib\site-packages\django\core\handlers\exception.py", line 34, in inner
    response = get_response(request)
  File "C:\Users\savek\Documents\spooner\project\pters-connect-venv\lib\site-packages\django\core\handlers\base.py", line 115, in _get_response
    response = self.process_exception_by_middleware(e, request)
  File "C:\Users\savek\Documents\spooner\project\pters-connect-venv\lib\site-packages\django\core\handlers\base.py", line 113, in _get_response
    response = wrapped_callback(request, *callback_args, **callback_kwargs)
  File "C:\Users\savek\Documents\spooner\project\pters-connect-venv\lib\site-packages\django\views\decorators\csrf.py", line 54, in wrapped_view
    return view_func(*args, **kwargs)
  File "C:\Users\savek\Documents\spooner\project\pters-connect-venv\lib\site-packages\rest_framework\viewsets.py", line 114, in view
    return self.dispatch(request, *args, **kwargs)
  File "C:\Users\savek\Documents\spooner\project\pters-connect-venv\lib\site-packages\rest_framework\views.py", line 505, in dispatch
    response = self.handle_exception(exc)
  File "C:\Users\savek\Documents\spooner\project\pters-connect-venv\lib\site-packages\rest_framework\views.py", line 465, in handle_exception
    self.raise_uncaught_exception(exc)
  File "C:\Users\savek\Documents\spooner\project\pters-connect-venv\lib\site-packages\rest_framework\views.py", line 476, in raise_uncaught_exception
    raise exc
  File "C:\Users\savek\Documents\spooner\project\pters-connect-venv\lib\site-packages\rest_framework\views.py", line 502, in dispatch
    response = handler(request, *args, **kwargs)
  File "C:\Users\savek\Documents\spooner\project\pters-connect\pters_connect\api\facility\viewsets.py", line 45, in with_subjects
    serializer.initial_data()
TypeError: 'FacilityTb' object is not callable
[30/Aug/2020 02:17:03] ERROR [django.server:157] "GET /facility/2/with_subjects/ HTTP/1.1" 500 26217
[30/Aug/2020 02:17:45] ERROR [django.request:228] Internal Server Error: /facility/2/with_subjects/
Traceback (most recent call last):
  File "C:\Users\savek\Documents\spooner\project\pters-connect-venv\lib\site-packages\django\core\handlers\exception.py", line 34, in inner
    response = get_response(request)
  File "C:\Users\savek\Documents\spooner\project\pters-connect-venv\lib\site-packages\django\core\handlers\base.py", line 115, in _get_response
    response = self.process_exception_by_middleware(e, request)
  File "C:\Users\savek\Documents\spooner\project\pters-connect-venv\lib\site-packages\django\core\handlers\base.py", line 113, in _get_response
    response = wrapped_callback(request, *callback_args, **callback_kwargs)
  File "C:\Users\savek\Documents\spooner\project\pters-connect-venv\lib\site-packages\django\views\decorators\csrf.py", line 54, in wrapped_view
    return view_func(*args, **kwargs)
  File "C:\Users\savek\Documents\spooner\project\pters-connect-venv\lib\site-packages\rest_framework\viewsets.py", line 114, in view
    return self.dispatch(request, *args, **kwargs)
  File "C:\Users\savek\Documents\spooner\project\pters-connect-venv\lib\site-packages\rest_framework\views.py", line 505, in dispatch
    response = self.handle_exception(exc)
  File "C:\Users\savek\Documents\spooner\project\pters-connect-venv\lib\site-packages\rest_framework\views.py", line 465, in handle_exception
    self.raise_uncaught_exception(exc)
  File "C:\Users\savek\Documents\spooner\project\pters-connect-venv\lib\site-packages\rest_framework\views.py", line 476, in raise_uncaught_exception
    raise exc
  File "C:\Users\savek\Documents\spooner\project\pters-connect-venv\lib\site-packages\rest_framework\views.py", line 502, in dispatch
    response = handler(request, *args, **kwargs)
  File "C:\Users\savek\Documents\spooner\project\pters-connect\pters_connect\api\facility\viewsets.py", line 44, in with_subjects
    serializer = self.get_serializer(data=facility_info.initial_data())
AttributeError: 'FacilityTb' object has no attribute 'initial_data'
[30/Aug/2020 02:17:45] ERROR [django.server:157] "GET /facility/2/with_subjects/ HTTP/1.1" 500 26301
[30/Aug/2020 02:18:14] ERROR [django.request:228] Internal Server Error: /facility/2/with_subjects/
Traceback (most recent call last):
  File "C:\Users\savek\Documents\spooner\project\pters-connect-venv\lib\site-packages\django\core\handlers\exception.py", line 34, in inner
    response = get_response(request)
  File "C:\Users\savek\Documents\spooner\project\pters-connect-venv\lib\site-packages\django\core\handlers\base.py", line 115, in _get_response
    response = self.process_exception_by_middleware(e, request)
  File "C:\Users\savek\Documents\spooner\project\pters-connect-venv\lib\site-packages\django\core\handlers\base.py", line 113, in _get_response
    response = wrapped_callback(request, *callback_args, **callback_kwargs)
  File "C:\Users\savek\Documents\spooner\project\pters-connect-venv\lib\site-packages\django\views\decorators\csrf.py", line 54, in wrapped_view
    return view_func(*args, **kwargs)
  File "C:\Users\savek\Documents\spooner\project\pters-connect-venv\lib\site-packages\rest_framework\viewsets.py", line 114, in view
    return self.dispatch(request, *args, **kwargs)
  File "C:\Users\savek\Documents\spooner\project\pters-connect-venv\lib\site-packages\rest_framework\views.py", line 505, in dispatch
    response = self.handle_exception(exc)
  File "C:\Users\savek\Documents\spooner\project\pters-connect-venv\lib\site-packages\rest_framework\views.py", line 465, in handle_exception
    self.raise_uncaught_exception(exc)
  File "C:\Users\savek\Documents\spooner\project\pters-connect-venv\lib\site-packages\rest_framework\views.py", line 476, in raise_uncaught_exception
    raise exc
  File "C:\Users\savek\Documents\spooner\project\pters-connect-venv\lib\site-packages\rest_framework\views.py", line 502, in dispatch
    response = handler(request, *args, **kwargs)
  File "C:\Users\savek\Documents\spooner\project\pters-connect\pters_connect\api\facility\viewsets.py", line 46, in with_subjects
    return Response(data=serializer.initial_data())
TypeError: 'FacilityTb' object is not callable
[30/Aug/2020 02:18:14] ERROR [django.server:157] "GET /facility/2/with_subjects/ HTTP/1.1" 500 26239
[30/Aug/2020 02:18:30] ERROR [django.request:228] Internal Server Error: /facility/2/with_subjects/
Traceback (most recent call last):
  File "C:\Users\savek\Documents\spooner\project\pters-connect-venv\lib\site-packages\django\core\handlers\exception.py", line 34, in inner
    response = get_response(request)
  File "C:\Users\savek\Documents\spooner\project\pters-connect-venv\lib\site-packages\django\core\handlers\base.py", line 115, in _get_response
    response = self.process_exception_by_middleware(e, request)
  File "C:\Users\savek\Documents\spooner\project\pters-connect-venv\lib\site-packages\django\core\handlers\base.py", line 113, in _get_response
    response = wrapped_callback(request, *callback_args, **callback_kwargs)
  File "C:\Users\savek\Documents\spooner\project\pters-connect-venv\lib\site-packages\django\views\decorators\csrf.py", line 54, in wrapped_view
    return view_func(*args, **kwargs)
  File "C:\Users\savek\Documents\spooner\project\pters-connect-venv\lib\site-packages\rest_framework\viewsets.py", line 114, in view
    return self.dispatch(request, *args, **kwargs)
  File "C:\Users\savek\Documents\spooner\project\pters-connect-venv\lib\site-packages\rest_framework\views.py", line 505, in dispatch
    response = self.handle_exception(exc)
  File "C:\Users\savek\Documents\spooner\project\pters-connect-venv\lib\site-packages\rest_framework\views.py", line 465, in handle_exception
    self.raise_uncaught_exception(exc)
  File "C:\Users\savek\Documents\spooner\project\pters-connect-venv\lib\site-packages\rest_framework\views.py", line 476, in raise_uncaught_exception
    raise exc
  File "C:\Users\savek\Documents\spooner\project\pters-connect-venv\lib\site-packages\rest_framework\views.py", line 502, in dispatch
    response = handler(request, *args, **kwargs)
  File "C:\Users\savek\Documents\spooner\project\pters-connect\pters_connect\api\facility\viewsets.py", line 46, in with_subjects
    return Response(data=serializer.initial_data())
TypeError: 'FacilityTb' object is not callable
[30/Aug/2020 02:18:30] ERROR [django.server:157] "GET /facility/2/with_subjects/ HTTP/1.1" 500 26239
[30/Aug/2020 02:19:06] ERROR [django.request:228] Internal Server Error: /facility/2/with_subjects/
Traceback (most recent call last):
  File "C:\Users\savek\Documents\spooner\project\pters-connect-venv\lib\site-packages\django\core\handlers\exception.py", line 34, in inner
    response = get_response(request)
  File "C:\Users\savek\Documents\spooner\project\pters-connect-venv\lib\site-packages\django\core\handlers\base.py", line 115, in _get_response
    response = self.process_exception_by_middleware(e, request)
  File "C:\Users\savek\Documents\spooner\project\pters-connect-venv\lib\site-packages\django\core\handlers\base.py", line 113, in _get_response
    response = wrapped_callback(request, *callback_args, **callback_kwargs)
  File "C:\Users\savek\Documents\spooner\project\pters-connect-venv\lib\site-packages\django\views\decorators\csrf.py", line 54, in wrapped_view
    return view_func(*args, **kwargs)
  File "C:\Users\savek\Documents\spooner\project\pters-connect-venv\lib\site-packages\rest_framework\viewsets.py", line 114, in view
    return self.dispatch(request, *args, **kwargs)
  File "C:\Users\savek\Documents\spooner\project\pters-connect-venv\lib\site-packages\rest_framework\views.py", line 505, in dispatch
    response = self.handle_exception(exc)
  File "C:\Users\savek\Documents\spooner\project\pters-connect-venv\lib\site-packages\rest_framework\views.py", line 465, in handle_exception
    self.raise_uncaught_exception(exc)
  File "C:\Users\savek\Documents\spooner\project\pters-connect-venv\lib\site-packages\rest_framework\views.py", line 476, in raise_uncaught_exception
    raise exc
  File "C:\Users\savek\Documents\spooner\project\pters-connect-venv\lib\site-packages\rest_framework\views.py", line 502, in dispatch
    response = handler(request, *args, **kwargs)
  File "C:\Users\savek\Documents\spooner\project\pters-connect\pters_connect\api\facility\viewsets.py", line 46, in with_subjects
    return Response(data=serializer.data)
  File "C:\Users\savek\Documents\spooner\project\pters-connect-venv\lib\site-packages\rest_framework\serializers.py", line 562, in data
    ret = super().data
  File "C:\Users\savek\Documents\spooner\project\pters-connect-venv\lib\site-packages\rest_framework\serializers.py", line 256, in data
    raise AssertionError(msg)
AssertionError: When a serializer is passed a `data` keyword argument you must call `.is_valid()` before attempting to access the serialized `.data` representation.
You should either call `.is_valid()` first, or access `.initial_data` instead.
[30/Aug/2020 02:19:06] ERROR [django.server:157] "GET /facility/2/with_subjects/ HTTP/1.1" 500 26948
[30/Aug/2020 02:57:02] ERROR [django.request:228] Internal Server Error: /member/get_sms_auth_number/
Traceback (most recent call last):
  File "C:\Users\savek\Documents\spooner\project\pters-connect-venv\lib\site-packages\django\core\handlers\exception.py", line 34, in inner
    response = get_response(request)
  File "C:\Users\savek\Documents\spooner\project\pters-connect-venv\lib\site-packages\django\core\handlers\base.py", line 115, in _get_response
    response = self.process_exception_by_middleware(e, request)
  File "C:\Users\savek\Documents\spooner\project\pters-connect-venv\lib\site-packages\django\core\handlers\base.py", line 113, in _get_response
    response = wrapped_callback(request, *callback_args, **callback_kwargs)
  File "C:\Users\savek\Documents\spooner\project\pters-connect-venv\lib\site-packages\django\views\decorators\csrf.py", line 54, in wrapped_view
    return view_func(*args, **kwargs)
  File "C:\Users\savek\Documents\spooner\project\pters-connect-venv\lib\site-packages\rest_framework\viewsets.py", line 114, in view
    return self.dispatch(request, *args, **kwargs)
  File "C:\Users\savek\Documents\spooner\project\pters-connect-venv\lib\site-packages\rest_framework\views.py", line 505, in dispatch
    response = self.handle_exception(exc)
  File "C:\Users\savek\Documents\spooner\project\pters-connect-venv\lib\site-packages\rest_framework\views.py", line 465, in handle_exception
    self.raise_uncaught_exception(exc)
  File "C:\Users\savek\Documents\spooner\project\pters-connect-venv\lib\site-packages\rest_framework\views.py", line 476, in raise_uncaught_exception
    raise exc
  File "C:\Users\savek\Documents\spooner\project\pters-connect-venv\lib\site-packages\rest_framework\views.py", line 502, in dispatch
    response = handler(request, *args, **kwargs)
  File "C:\Users\savek\Documents\spooner\project\pters-connect\pters_connect\api\member\viewsets.py", line 74, in get_sms_auth_number
    print(str(serializer.data))
  File "C:\Users\savek\Documents\spooner\project\pters-connect-venv\lib\site-packages\rest_framework\serializers.py", line 562, in data
    ret = super().data
  File "C:\Users\savek\Documents\spooner\project\pters-connect-venv\lib\site-packages\rest_framework\serializers.py", line 256, in data
    raise AssertionError(msg)
AssertionError: When a serializer is passed a `data` keyword argument you must call `.is_valid()` before attempting to access the serialized `.data` representation.
You should either call `.is_valid()` first, or access `.initial_data` instead.
[30/Aug/2020 02:57:02] ERROR [django.server:157] "POST /member/get_sms_auth_number/ HTTP/1.1" 500 26998
[30/Aug/2020 02:59:28] ERROR [django.request:228] Internal Server Error: /member/get_sms_auth_number/
Traceback (most recent call last):
  File "C:\Users\savek\Documents\spooner\project\pters-connect-venv\lib\site-packages\django\core\handlers\exception.py", line 34, in inner
    response = get_response(request)
  File "C:\Users\savek\Documents\spooner\project\pters-connect-venv\lib\site-packages\django\core\handlers\base.py", line 115, in _get_response
    response = self.process_exception_by_middleware(e, request)
  File "C:\Users\savek\Documents\spooner\project\pters-connect-venv\lib\site-packages\django\core\handlers\base.py", line 113, in _get_response
    response = wrapped_callback(request, *callback_args, **callback_kwargs)
  File "C:\Users\savek\Documents\spooner\project\pters-connect-venv\lib\site-packages\django\views\decorators\csrf.py", line 54, in wrapped_view
    return view_func(*args, **kwargs)
  File "C:\Users\savek\Documents\spooner\project\pters-connect-venv\lib\site-packages\rest_framework\viewsets.py", line 114, in view
    return self.dispatch(request, *args, **kwargs)
  File "C:\Users\savek\Documents\spooner\project\pters-connect-venv\lib\site-packages\rest_framework\views.py", line 505, in dispatch
    response = self.handle_exception(exc)
  File "C:\Users\savek\Documents\spooner\project\pters-connect-venv\lib\site-packages\rest_framework\views.py", line 465, in handle_exception
    self.raise_uncaught_exception(exc)
  File "C:\Users\savek\Documents\spooner\project\pters-connect-venv\lib\site-packages\rest_framework\views.py", line 476, in raise_uncaught_exception
    raise exc
  File "C:\Users\savek\Documents\spooner\project\pters-connect-venv\lib\site-packages\rest_framework\views.py", line 502, in dispatch
    response = handler(request, *args, **kwargs)
  File "C:\Users\savek\Documents\spooner\project\pters-connect\pters_connect\api\member\viewsets.py", line 76, in get_sms_auth_number
    serializer.save()
TypeError: save() missing 1 required positional argument: 'validated_data'
[30/Aug/2020 02:59:28] ERROR [django.server:157] "POST /member/get_sms_auth_number/ HTTP/1.1" 500 26325
[30/Aug/2020 03:00:41] ERROR [django.request:228] Internal Server Error: /member/get_sms_auth_number/
Traceback (most recent call last):
  File "C:\Users\savek\Documents\spooner\project\pters-connect-venv\lib\site-packages\django\core\handlers\exception.py", line 34, in inner
    response = get_response(request)
  File "C:\Users\savek\Documents\spooner\project\pters-connect-venv\lib\site-packages\django\core\handlers\base.py", line 115, in _get_response
    response = self.process_exception_by_middleware(e, request)
  File "C:\Users\savek\Documents\spooner\project\pters-connect-venv\lib\site-packages\django\core\handlers\base.py", line 113, in _get_response
    response = wrapped_callback(request, *callback_args, **callback_kwargs)
  File "C:\Users\savek\Documents\spooner\project\pters-connect-venv\lib\site-packages\django\views\decorators\csrf.py", line 54, in wrapped_view
    return view_func(*args, **kwargs)
  File "C:\Users\savek\Documents\spooner\project\pters-connect-venv\lib\site-packages\rest_framework\viewsets.py", line 114, in view
    return self.dispatch(request, *args, **kwargs)
  File "C:\Users\savek\Documents\spooner\project\pters-connect-venv\lib\site-packages\rest_framework\views.py", line 505, in dispatch
    response = self.handle_exception(exc)
  File "C:\Users\savek\Documents\spooner\project\pters-connect-venv\lib\site-packages\rest_framework\views.py", line 465, in handle_exception
    self.raise_uncaught_exception(exc)
  File "C:\Users\savek\Documents\spooner\project\pters-connect-venv\lib\site-packages\rest_framework\views.py", line 476, in raise_uncaught_exception
    raise exc
  File "C:\Users\savek\Documents\spooner\project\pters-connect-venv\lib\site-packages\rest_framework\views.py", line 502, in dispatch
    response = handler(request, *args, **kwargs)
  File "C:\Users\savek\Documents\spooner\project\pters-connect\pters_connect\api\member\viewsets.py", line 79, in get_sms_auth_number
    error = func_send_sms_auth(serializer['phone_number'], serializer['auth_number'], 'PTERS-CONNECT')
  File "C:\Users\savek\Documents\spooner\project\pters-connect-venv\lib\site-packages\rest_framework\serializers.py", line 548, in __getitem__
    field = self.fields[key]
  File "C:\Users\savek\Documents\spooner\project\pters-connect-venv\lib\site-packages\rest_framework\utils\serializer_helpers.py", line 148, in __getitem__
    return self.fields[key]
KeyError: 'auth_number'
[30/Aug/2020 03:00:41] ERROR [django.server:157] "POST /member/get_sms_auth_number/ HTTP/1.1" 500 26660
[30/Aug/2020 03:01:45] ERROR [django.request:228] Internal Server Error: /member/get_sms_auth_number/
Traceback (most recent call last):
  File "C:\Users\savek\Documents\spooner\project\pters-connect-venv\lib\site-packages\django\core\handlers\exception.py", line 34, in inner
    response = get_response(request)
  File "C:\Users\savek\Documents\spooner\project\pters-connect-venv\lib\site-packages\django\core\handlers\base.py", line 115, in _get_response
    response = self.process_exception_by_middleware(e, request)
  File "C:\Users\savek\Documents\spooner\project\pters-connect-venv\lib\site-packages\django\core\handlers\base.py", line 113, in _get_response
    response = wrapped_callback(request, *callback_args, **callback_kwargs)
  File "C:\Users\savek\Documents\spooner\project\pters-connect-venv\lib\site-packages\django\views\decorators\csrf.py", line 54, in wrapped_view
    return view_func(*args, **kwargs)
  File "C:\Users\savek\Documents\spooner\project\pters-connect-venv\lib\site-packages\rest_framework\viewsets.py", line 114, in view
    return self.dispatch(request, *args, **kwargs)
  File "C:\Users\savek\Documents\spooner\project\pters-connect-venv\lib\site-packages\rest_framework\views.py", line 505, in dispatch
    response = self.handle_exception(exc)
  File "C:\Users\savek\Documents\spooner\project\pters-connect-venv\lib\site-packages\rest_framework\views.py", line 465, in handle_exception
    self.raise_uncaught_exception(exc)
  File "C:\Users\savek\Documents\spooner\project\pters-connect-venv\lib\site-packages\rest_framework\views.py", line 476, in raise_uncaught_exception
    raise exc
  File "C:\Users\savek\Documents\spooner\project\pters-connect-venv\lib\site-packages\rest_framework\views.py", line 502, in dispatch
    response = handler(request, *args, **kwargs)
  File "C:\Users\savek\Documents\spooner\project\pters-connect\pters_connect\api\member\viewsets.py", line 79, in get_sms_auth_number
    error = func_send_sms_auth(serializer['phone_number'], serializer['auth_number'], 'PTERS-CONNECT')
  File "C:\Users\savek\Documents\spooner\project\pters-connect-venv\lib\site-packages\rest_framework\serializers.py", line 548, in __getitem__
    field = self.fields[key]
  File "C:\Users\savek\Documents\spooner\project\pters-connect-venv\lib\site-packages\rest_framework\utils\serializer_helpers.py", line 148, in __getitem__
    return self.fields[key]
KeyError: 'auth_number'
[30/Aug/2020 03:01:45] ERROR [django.server:157] "POST /member/get_sms_auth_number/ HTTP/1.1" 500 26660
[30/Aug/2020 03:06:21] ERROR [django.request:228] Internal Server Error: /member/get_sms_auth_number/
Traceback (most recent call last):
  File "C:\Users\savek\Documents\spooner\project\pters-connect-venv\lib\site-packages\django\core\handlers\exception.py", line 34, in inner
    response = get_response(request)
  File "C:\Users\savek\Documents\spooner\project\pters-connect-venv\lib\site-packages\django\core\handlers\base.py", line 115, in _get_response
    response = self.process_exception_by_middleware(e, request)
  File "C:\Users\savek\Documents\spooner\project\pters-connect-venv\lib\site-packages\django\core\handlers\base.py", line 113, in _get_response
    response = wrapped_callback(request, *callback_args, **callback_kwargs)
  File "C:\Users\savek\Documents\spooner\project\pters-connect-venv\lib\site-packages\django\views\decorators\csrf.py", line 54, in wrapped_view
    return view_func(*args, **kwargs)
  File "C:\Users\savek\Documents\spooner\project\pters-connect-venv\lib\site-packages\rest_framework\viewsets.py", line 114, in view
    return self.dispatch(request, *args, **kwargs)
  File "C:\Users\savek\Documents\spooner\project\pters-connect-venv\lib\site-packages\rest_framework\views.py", line 505, in dispatch
    response = self.handle_exception(exc)
  File "C:\Users\savek\Documents\spooner\project\pters-connect-venv\lib\site-packages\rest_framework\views.py", line 465, in handle_exception
    self.raise_uncaught_exception(exc)
  File "C:\Users\savek\Documents\spooner\project\pters-connect-venv\lib\site-packages\rest_framework\views.py", line 476, in raise_uncaught_exception
    raise exc
  File "C:\Users\savek\Documents\spooner\project\pters-connect-venv\lib\site-packages\rest_framework\views.py", line 502, in dispatch
    response = handler(request, *args, **kwargs)
  File "C:\Users\savek\Documents\spooner\project\pters-connect\pters_connect\api\member\viewsets.py", line 75, in get_sms_auth_number
    serializer.save()
  File "C:\Users\savek\Documents\spooner\project\pters-connect\pters_connect\api\member\serializers.py", line 158, in save
    error = func_send_sms_auth(kwargs['phone_number'], kwargs['auth_number'], 'PTERS-CONNECT')
KeyError: 'phone_number'
[30/Aug/2020 03:06:21] ERROR [django.server:157] "POST /member/get_sms_auth_number/ HTTP/1.1" 500 26443
[30/Aug/2020 03:07:14] ERROR [django.request:228] Internal Server Error: /member/get_sms_auth_number/
Traceback (most recent call last):
  File "C:\Users\savek\Documents\spooner\project\pters-connect-venv\lib\site-packages\django\core\handlers\exception.py", line 34, in inner
    response = get_response(request)
  File "C:\Users\savek\Documents\spooner\project\pters-connect-venv\lib\site-packages\django\core\handlers\base.py", line 115, in _get_response
    response = self.process_exception_by_middleware(e, request)
  File "C:\Users\savek\Documents\spooner\project\pters-connect-venv\lib\site-packages\django\core\handlers\base.py", line 113, in _get_response
    response = wrapped_callback(request, *callback_args, **callback_kwargs)
  File "C:\Users\savek\Documents\spooner\project\pters-connect-venv\lib\site-packages\django\views\decorators\csrf.py", line 54, in wrapped_view
    return view_func(*args, **kwargs)
  File "C:\Users\savek\Documents\spooner\project\pters-connect-venv\lib\site-packages\rest_framework\viewsets.py", line 114, in view
    return self.dispatch(request, *args, **kwargs)
  File "C:\Users\savek\Documents\spooner\project\pters-connect-venv\lib\site-packages\rest_framework\views.py", line 505, in dispatch
    response = self.handle_exception(exc)
  File "C:\Users\savek\Documents\spooner\project\pters-connect-venv\lib\site-packages\rest_framework\views.py", line 465, in handle_exception
    self.raise_uncaught_exception(exc)
  File "C:\Users\savek\Documents\spooner\project\pters-connect-venv\lib\site-packages\rest_framework\views.py", line 476, in raise_uncaught_exception
    raise exc
  File "C:\Users\savek\Documents\spooner\project\pters-connect-venv\lib\site-packages\rest_framework\views.py", line 502, in dispatch
    response = handler(request, *args, **kwargs)
  File "C:\Users\savek\Documents\spooner\project\pters-connect\pters_connect\api\member\viewsets.py", line 75, in get_sms_auth_number
    serializer.save()
  File "C:\Users\savek\Documents\spooner\project\pters-connect\pters_connect\api\member\serializers.py", line 158, in save
    error = func_send_sms_auth(kwargs['phone_number'], kwargs['auth_number'], 'PTERS-CONNECT')
KeyError: 'phone_number'
[30/Aug/2020 03:07:14] ERROR [django.server:157] "POST /member/get_sms_auth_number/ HTTP/1.1" 500 26443
[30/Aug/2020 03:07:30] ERROR [django.request:228] Internal Server Error: /member/get_sms_auth_number/
Traceback (most recent call last):
  File "C:\Users\savek\Documents\spooner\project\pters-connect-venv\lib\site-packages\django\core\handlers\exception.py", line 34, in inner
    response = get_response(request)
  File "C:\Users\savek\Documents\spooner\project\pters-connect-venv\lib\site-packages\django\core\handlers\base.py", line 115, in _get_response
    response = self.process_exception_by_middleware(e, request)
  File "C:\Users\savek\Documents\spooner\project\pters-connect-venv\lib\site-packages\django\core\handlers\base.py", line 113, in _get_response
    response = wrapped_callback(request, *callback_args, **callback_kwargs)
  File "C:\Users\savek\Documents\spooner\project\pters-connect-venv\lib\site-packages\django\views\decorators\csrf.py", line 54, in wrapped_view
    return view_func(*args, **kwargs)
  File "C:\Users\savek\Documents\spooner\project\pters-connect-venv\lib\site-packages\rest_framework\viewsets.py", line 114, in view
    return self.dispatch(request, *args, **kwargs)
  File "C:\Users\savek\Documents\spooner\project\pters-connect-venv\lib\site-packages\rest_framework\views.py", line 505, in dispatch
    response = self.handle_exception(exc)
  File "C:\Users\savek\Documents\spooner\project\pters-connect-venv\lib\site-packages\rest_framework\views.py", line 465, in handle_exception
    self.raise_uncaught_exception(exc)
  File "C:\Users\savek\Documents\spooner\project\pters-connect-venv\lib\site-packages\rest_framework\views.py", line 476, in raise_uncaught_exception
    raise exc
  File "C:\Users\savek\Documents\spooner\project\pters-connect-venv\lib\site-packages\rest_framework\views.py", line 502, in dispatch
    response = handler(request, *args, **kwargs)
  File "C:\Users\savek\Documents\spooner\project\pters-connect\pters_connect\api\member\viewsets.py", line 75, in get_sms_auth_number
    serializer.save()
  File "C:\Users\savek\Documents\spooner\project\pters-connect\pters_connect\api\member\serializers.py", line 159, in save
    error = func_send_sms_auth(kwargs['phone_number'], kwargs['auth_number'], 'PTERS-CONNECT')
KeyError: 'phone_number'
[30/Aug/2020 03:07:30] ERROR [django.server:157] "POST /member/get_sms_auth_number/ HTTP/1.1" 500 26443
[30/Aug/2020 03:08:09] ERROR [django.request:228] Internal Server Error: /member/get_sms_auth_number/
Traceback (most recent call last):
  File "C:\Users\savek\Documents\spooner\project\pters-connect-venv\lib\site-packages\django\core\handlers\exception.py", line 34, in inner
    response = get_response(request)
  File "C:\Users\savek\Documents\spooner\project\pters-connect-venv\lib\site-packages\django\core\handlers\base.py", line 115, in _get_response
    response = self.process_exception_by_middleware(e, request)
  File "C:\Users\savek\Documents\spooner\project\pters-connect-venv\lib\site-packages\django\core\handlers\base.py", line 113, in _get_response
    response = wrapped_callback(request, *callback_args, **callback_kwargs)
  File "C:\Users\savek\Documents\spooner\project\pters-connect-venv\lib\site-packages\django\views\decorators\csrf.py", line 54, in wrapped_view
    return view_func(*args, **kwargs)
  File "C:\Users\savek\Documents\spooner\project\pters-connect-venv\lib\site-packages\rest_framework\viewsets.py", line 114, in view
    return self.dispatch(request, *args, **kwargs)
  File "C:\Users\savek\Documents\spooner\project\pters-connect-venv\lib\site-packages\rest_framework\views.py", line 505, in dispatch
    response = self.handle_exception(exc)
  File "C:\Users\savek\Documents\spooner\project\pters-connect-venv\lib\site-packages\rest_framework\views.py", line 465, in handle_exception
    self.raise_uncaught_exception(exc)
  File "C:\Users\savek\Documents\spooner\project\pters-connect-venv\lib\site-packages\rest_framework\views.py", line 476, in raise_uncaught_exception
    raise exc
  File "C:\Users\savek\Documents\spooner\project\pters-connect-venv\lib\site-packages\rest_framework\views.py", line 502, in dispatch
    response = handler(request, *args, **kwargs)
  File "C:\Users\savek\Documents\spooner\project\pters-connect\pters_connect\api\member\viewsets.py", line 75, in get_sms_auth_number
    serializer.save()
  File "C:\Users\savek\Documents\spooner\project\pters-connect\pters_connect\api\member\serializers.py", line 159, in save
    error = func_send_sms_auth(kwargs['phone_number'], kwargs['auth_number'], 'PTERS-CONNECT')
KeyError: 'phone_number'
[30/Aug/2020 03:08:09] ERROR [django.server:157] "POST /member/get_sms_auth_number/ HTTP/1.1" 500 26443
[30/Aug/2020 03:09:12] ERROR [django.request:228] Internal Server Error: /member/get_sms_auth_number/
Traceback (most recent call last):
  File "C:\Users\savek\Documents\spooner\project\pters-connect-venv\lib\site-packages\django\core\handlers\exception.py", line 34, in inner
    response = get_response(request)
  File "C:\Users\savek\Documents\spooner\project\pters-connect-venv\lib\site-packages\django\core\handlers\base.py", line 115, in _get_response
    response = self.process_exception_by_middleware(e, request)
  File "C:\Users\savek\Documents\spooner\project\pters-connect-venv\lib\site-packages\django\core\handlers\base.py", line 113, in _get_response
    response = wrapped_callback(request, *callback_args, **callback_kwargs)
  File "C:\Users\savek\Documents\spooner\project\pters-connect-venv\lib\site-packages\django\views\decorators\csrf.py", line 54, in wrapped_view
    return view_func(*args, **kwargs)
  File "C:\Users\savek\Documents\spooner\project\pters-connect-venv\lib\site-packages\rest_framework\viewsets.py", line 114, in view
    return self.dispatch(request, *args, **kwargs)
  File "C:\Users\savek\Documents\spooner\project\pters-connect-venv\lib\site-packages\rest_framework\views.py", line 505, in dispatch
    response = self.handle_exception(exc)
  File "C:\Users\savek\Documents\spooner\project\pters-connect-venv\lib\site-packages\rest_framework\views.py", line 465, in handle_exception
    self.raise_uncaught_exception(exc)
  File "C:\Users\savek\Documents\spooner\project\pters-connect-venv\lib\site-packages\rest_framework\views.py", line 476, in raise_uncaught_exception
    raise exc
  File "C:\Users\savek\Documents\spooner\project\pters-connect-venv\lib\site-packages\rest_framework\views.py", line 502, in dispatch
    response = handler(request, *args, **kwargs)
  File "C:\Users\savek\Documents\spooner\project\pters-connect\pters_connect\api\member\viewsets.py", line 75, in get_sms_auth_number
    serializer.save()
  File "C:\Users\savek\Documents\spooner\project\pters-connect\pters_connect\api\member\serializers.py", line 155, in save
    print(self.request)
AttributeError: 'SmsAuthCreateSerializer' object has no attribute 'request'
[30/Aug/2020 03:09:12] ERROR [django.server:157] "POST /member/get_sms_auth_number/ HTTP/1.1" 500 26474
[30/Aug/2020 03:09:53] ERROR [django.request:228] Internal Server Error: /member/get_sms_auth_number/
Traceback (most recent call last):
  File "C:\Users\savek\Documents\spooner\project\pters-connect-venv\lib\site-packages\django\core\handlers\exception.py", line 34, in inner
    response = get_response(request)
  File "C:\Users\savek\Documents\spooner\project\pters-connect-venv\lib\site-packages\django\core\handlers\base.py", line 115, in _get_response
    response = self.process_exception_by_middleware(e, request)
  File "C:\Users\savek\Documents\spooner\project\pters-connect-venv\lib\site-packages\django\core\handlers\base.py", line 113, in _get_response
    response = wrapped_callback(request, *callback_args, **callback_kwargs)
  File "C:\Users\savek\Documents\spooner\project\pters-connect-venv\lib\site-packages\django\views\decorators\csrf.py", line 54, in wrapped_view
    return view_func(*args, **kwargs)
  File "C:\Users\savek\Documents\spooner\project\pters-connect-venv\lib\site-packages\rest_framework\viewsets.py", line 114, in view
    return self.dispatch(request, *args, **kwargs)
  File "C:\Users\savek\Documents\spooner\project\pters-connect-venv\lib\site-packages\rest_framework\views.py", line 505, in dispatch
    response = self.handle_exception(exc)
  File "C:\Users\savek\Documents\spooner\project\pters-connect-venv\lib\site-packages\rest_framework\views.py", line 465, in handle_exception
    self.raise_uncaught_exception(exc)
  File "C:\Users\savek\Documents\spooner\project\pters-connect-venv\lib\site-packages\rest_framework\views.py", line 476, in raise_uncaught_exception
    raise exc
  File "C:\Users\savek\Documents\spooner\project\pters-connect-venv\lib\site-packages\rest_framework\views.py", line 502, in dispatch
    response = handler(request, *args, **kwargs)
  File "C:\Users\savek\Documents\spooner\project\pters-connect\pters_connect\api\member\viewsets.py", line 75, in get_sms_auth_number
    serializer.save()
  File "C:\Users\savek\Documents\spooner\project\pters-connect\pters_connect\api\member\serializers.py", line 159, in save
    error = func_send_sms_auth(kwargs['phone_number'], kwargs['auth_number'], 'PTERS-CONNECT')
KeyError: 'phone_number'
[30/Aug/2020 03:09:53] ERROR [django.server:157] "POST /member/get_sms_auth_number/ HTTP/1.1" 500 26443
<<<<<<< HEAD
[01/Sep/2020 15:31:56] ERROR [django.request:228] Internal Server Error: /facility/
Traceback (most recent call last):
  File "/home/ubuntu/.pyenv/versions/3.6.10/lib/python3.6/site-packages/django/db/backends/utils.py", line 86, in _execute
    return self.cursor.execute(sql, params)
  File "/home/ubuntu/.pyenv/versions/3.6.10/lib/python3.6/site-packages/django/db/backends/mysql/base.py", line 74, in execute
    return self.cursor.execute(query, args)
  File "/home/ubuntu/.pyenv/versions/3.6.10/lib/python3.6/site-packages/pymysql/cursors.py", line 163, in execute
    result = self._query(query)
  File "/home/ubuntu/.pyenv/versions/3.6.10/lib/python3.6/site-packages/pymysql/cursors.py", line 321, in _query
    conn.query(q)
  File "/home/ubuntu/.pyenv/versions/3.6.10/lib/python3.6/site-packages/pymysql/connections.py", line 505, in query
    self._affected_rows = self._read_query_result(unbuffered=unbuffered)
  File "/home/ubuntu/.pyenv/versions/3.6.10/lib/python3.6/site-packages/pymysql/connections.py", line 724, in _read_query_result
    result.read()
  File "/home/ubuntu/.pyenv/versions/3.6.10/lib/python3.6/site-packages/pymysql/connections.py", line 1069, in read
    first_packet = self.connection._read_packet()
  File "/home/ubuntu/.pyenv/versions/3.6.10/lib/python3.6/site-packages/pymysql/connections.py", line 676, in _read_packet
    packet.raise_for_error()
  File "/home/ubuntu/.pyenv/versions/3.6.10/lib/python3.6/site-packages/pymysql/protocol.py", line 223, in raise_for_error
    err.raise_mysql_exception(self._data)
  File "/home/ubuntu/.pyenv/versions/3.6.10/lib/python3.6/site-packages/pymysql/err.py", line 107, in raise_mysql_exception
    raise errorclass(errno, errval)
pymysql.err.OperationalError: (1054, "Unknown column 'FACILITY_TB.CONTACT_NUMBER' in 'field list'")

The above exception was the direct cause of the following exception:

Traceback (most recent call last):
  File "/home/ubuntu/.pyenv/versions/3.6.10/lib/python3.6/site-packages/django/core/handlers/exception.py", line 34, in inner
    response = get_response(request)
  File "/home/ubuntu/.pyenv/versions/3.6.10/lib/python3.6/site-packages/django/core/handlers/base.py", line 115, in _get_response
    response = self.process_exception_by_middleware(e, request)
  File "/home/ubuntu/.pyenv/versions/3.6.10/lib/python3.6/site-packages/django/core/handlers/base.py", line 113, in _get_response
    response = wrapped_callback(request, *callback_args, **callback_kwargs)
  File "/home/ubuntu/.pyenv/versions/3.6.10/lib/python3.6/site-packages/django/views/decorators/csrf.py", line 54, in wrapped_view
    return view_func(*args, **kwargs)
  File "/home/ubuntu/.pyenv/versions/3.6.10/lib/python3.6/site-packages/rest_framework/viewsets.py", line 114, in view
    return self.dispatch(request, *args, **kwargs)
  File "/home/ubuntu/.pyenv/versions/3.6.10/lib/python3.6/site-packages/rest_framework/views.py", line 505, in dispatch
    response = self.handle_exception(exc)
  File "/home/ubuntu/.pyenv/versions/3.6.10/lib/python3.6/site-packages/rest_framework/views.py", line 465, in handle_exception
    self.raise_uncaught_exception(exc)
  File "/home/ubuntu/.pyenv/versions/3.6.10/lib/python3.6/site-packages/rest_framework/views.py", line 476, in raise_uncaught_exception
    raise exc
  File "/home/ubuntu/.pyenv/versions/3.6.10/lib/python3.6/site-packages/rest_framework/views.py", line 502, in dispatch
    response = handler(request, *args, **kwargs)
  File "/home/ubuntu/.pyenv/versions/3.6.10/lib/python3.6/site-packages/rest_framework/mixins.py", line 40, in list
    page = self.paginate_queryset(queryset)
  File "/home/ubuntu/.pyenv/versions/3.6.10/lib/python3.6/site-packages/rest_framework/generics.py", line 171, in paginate_queryset
    return self.paginator.paginate_queryset(queryset, self.request, view=self)
  File "/home/ubuntu/.pyenv/versions/3.6.10/lib/python3.6/site-packages/rest_framework/pagination.py", line 218, in paginate_queryset
    return list(self.page)
  File "/home/ubuntu/.pyenv/versions/3.6.10/lib/python3.6/site-packages/django/core/paginator.py", line 150, in __len__
    return len(self.object_list)
  File "/home/ubuntu/.pyenv/versions/3.6.10/lib/python3.6/site-packages/django/db/models/query.py", line 258, in __len__
    self._fetch_all()
  File "/home/ubuntu/.pyenv/versions/3.6.10/lib/python3.6/site-packages/django/db/models/query.py", line 1261, in _fetch_all
    self._result_cache = list(self._iterable_class(self))
  File "/home/ubuntu/.pyenv/versions/3.6.10/lib/python3.6/site-packages/django/db/models/query.py", line 57, in __iter__
    results = compiler.execute_sql(chunked_fetch=self.chunked_fetch, chunk_size=self.chunk_size)
  File "/home/ubuntu/.pyenv/versions/3.6.10/lib/python3.6/site-packages/django/db/models/sql/compiler.py", line 1137, in execute_sql
    cursor.execute(sql, params)
  File "/home/ubuntu/.pyenv/versions/3.6.10/lib/python3.6/site-packages/django/db/backends/utils.py", line 100, in execute
    return super().execute(sql, params)
  File "/home/ubuntu/.pyenv/versions/3.6.10/lib/python3.6/site-packages/django/db/backends/utils.py", line 68, in execute
    return self._execute_with_wrappers(sql, params, many=False, executor=self._execute)
  File "/home/ubuntu/.pyenv/versions/3.6.10/lib/python3.6/site-packages/django/db/backends/utils.py", line 77, in _execute_with_wrappers
    return executor(sql, params, many, context)
  File "/home/ubuntu/.pyenv/versions/3.6.10/lib/python3.6/site-packages/django/db/backends/utils.py", line 86, in _execute
    return self.cursor.execute(sql, params)
  File "/home/ubuntu/.pyenv/versions/3.6.10/lib/python3.6/site-packages/django/db/utils.py", line 90, in __exit__
    raise dj_exc_value.with_traceback(traceback) from exc_value
  File "/home/ubuntu/.pyenv/versions/3.6.10/lib/python3.6/site-packages/django/db/backends/utils.py", line 86, in _execute
    return self.cursor.execute(sql, params)
  File "/home/ubuntu/.pyenv/versions/3.6.10/lib/python3.6/site-packages/django/db/backends/mysql/base.py", line 74, in execute
    return self.cursor.execute(query, args)
  File "/home/ubuntu/.pyenv/versions/3.6.10/lib/python3.6/site-packages/pymysql/cursors.py", line 163, in execute
    result = self._query(query)
  File "/home/ubuntu/.pyenv/versions/3.6.10/lib/python3.6/site-packages/pymysql/cursors.py", line 321, in _query
    conn.query(q)
  File "/home/ubuntu/.pyenv/versions/3.6.10/lib/python3.6/site-packages/pymysql/connections.py", line 505, in query
    self._affected_rows = self._read_query_result(unbuffered=unbuffered)
  File "/home/ubuntu/.pyenv/versions/3.6.10/lib/python3.6/site-packages/pymysql/connections.py", line 724, in _read_query_result
    result.read()
  File "/home/ubuntu/.pyenv/versions/3.6.10/lib/python3.6/site-packages/pymysql/connections.py", line 1069, in read
    first_packet = self.connection._read_packet()
  File "/home/ubuntu/.pyenv/versions/3.6.10/lib/python3.6/site-packages/pymysql/connections.py", line 676, in _read_packet
    packet.raise_for_error()
  File "/home/ubuntu/.pyenv/versions/3.6.10/lib/python3.6/site-packages/pymysql/protocol.py", line 223, in raise_for_error
    err.raise_mysql_exception(self._data)
  File "/home/ubuntu/.pyenv/versions/3.6.10/lib/python3.6/site-packages/pymysql/err.py", line 107, in raise_mysql_exception
    raise errorclass(errno, errval)
django.db.utils.OperationalError: (1054, "Unknown column 'FACILITY_TB.CONTACT_NUMBER' in 'field list'")
[01/Sep/2020 15:34:47] ERROR [django.request:228] Internal Server Error: /facility/
Traceback (most recent call last):
  File "/home/ubuntu/.pyenv/versions/3.6.10/lib/python3.6/site-packages/django/db/backends/utils.py", line 86, in _execute
    return self.cursor.execute(sql, params)
  File "/home/ubuntu/.pyenv/versions/3.6.10/lib/python3.6/site-packages/django/db/backends/mysql/base.py", line 74, in execute
    return self.cursor.execute(query, args)
  File "/home/ubuntu/.pyenv/versions/3.6.10/lib/python3.6/site-packages/pymysql/cursors.py", line 163, in execute
    result = self._query(query)
  File "/home/ubuntu/.pyenv/versions/3.6.10/lib/python3.6/site-packages/pymysql/cursors.py", line 321, in _query
    conn.query(q)
  File "/home/ubuntu/.pyenv/versions/3.6.10/lib/python3.6/site-packages/pymysql/connections.py", line 505, in query
    self._affected_rows = self._read_query_result(unbuffered=unbuffered)
  File "/home/ubuntu/.pyenv/versions/3.6.10/lib/python3.6/site-packages/pymysql/connections.py", line 724, in _read_query_result
    result.read()
  File "/home/ubuntu/.pyenv/versions/3.6.10/lib/python3.6/site-packages/pymysql/connections.py", line 1069, in read
    first_packet = self.connection._read_packet()
  File "/home/ubuntu/.pyenv/versions/3.6.10/lib/python3.6/site-packages/pymysql/connections.py", line 676, in _read_packet
    packet.raise_for_error()
  File "/home/ubuntu/.pyenv/versions/3.6.10/lib/python3.6/site-packages/pymysql/protocol.py", line 223, in raise_for_error
    err.raise_mysql_exception(self._data)
  File "/home/ubuntu/.pyenv/versions/3.6.10/lib/python3.6/site-packages/pymysql/err.py", line 107, in raise_mysql_exception
    raise errorclass(errno, errval)
pymysql.err.OperationalError: (1054, "Unknown column 'FACILITY_TB.CONTACT_NUMBER' in 'field list'")

The above exception was the direct cause of the following exception:

Traceback (most recent call last):
  File "/home/ubuntu/.pyenv/versions/3.6.10/lib/python3.6/site-packages/django/core/handlers/exception.py", line 34, in inner
    response = get_response(request)
  File "/home/ubuntu/.pyenv/versions/3.6.10/lib/python3.6/site-packages/django/core/handlers/base.py", line 115, in _get_response
    response = self.process_exception_by_middleware(e, request)
  File "/home/ubuntu/.pyenv/versions/3.6.10/lib/python3.6/site-packages/django/core/handlers/base.py", line 113, in _get_response
    response = wrapped_callback(request, *callback_args, **callback_kwargs)
  File "/home/ubuntu/.pyenv/versions/3.6.10/lib/python3.6/site-packages/django/views/decorators/csrf.py", line 54, in wrapped_view
    return view_func(*args, **kwargs)
  File "/home/ubuntu/.pyenv/versions/3.6.10/lib/python3.6/site-packages/rest_framework/viewsets.py", line 114, in view
    return self.dispatch(request, *args, **kwargs)
  File "/home/ubuntu/.pyenv/versions/3.6.10/lib/python3.6/site-packages/rest_framework/views.py", line 505, in dispatch
    response = self.handle_exception(exc)
  File "/home/ubuntu/.pyenv/versions/3.6.10/lib/python3.6/site-packages/rest_framework/views.py", line 465, in handle_exception
    self.raise_uncaught_exception(exc)
  File "/home/ubuntu/.pyenv/versions/3.6.10/lib/python3.6/site-packages/rest_framework/views.py", line 476, in raise_uncaught_exception
    raise exc
  File "/home/ubuntu/.pyenv/versions/3.6.10/lib/python3.6/site-packages/rest_framework/views.py", line 502, in dispatch
    response = handler(request, *args, **kwargs)
  File "/home/ubuntu/.pyenv/versions/3.6.10/lib/python3.6/site-packages/rest_framework/mixins.py", line 40, in list
    page = self.paginate_queryset(queryset)
  File "/home/ubuntu/.pyenv/versions/3.6.10/lib/python3.6/site-packages/rest_framework/generics.py", line 171, in paginate_queryset
    return self.paginator.paginate_queryset(queryset, self.request, view=self)
  File "/home/ubuntu/.pyenv/versions/3.6.10/lib/python3.6/site-packages/rest_framework/pagination.py", line 218, in paginate_queryset
    return list(self.page)
  File "/home/ubuntu/.pyenv/versions/3.6.10/lib/python3.6/site-packages/django/core/paginator.py", line 150, in __len__
    return len(self.object_list)
  File "/home/ubuntu/.pyenv/versions/3.6.10/lib/python3.6/site-packages/django/db/models/query.py", line 258, in __len__
    self._fetch_all()
  File "/home/ubuntu/.pyenv/versions/3.6.10/lib/python3.6/site-packages/django/db/models/query.py", line 1261, in _fetch_all
    self._result_cache = list(self._iterable_class(self))
  File "/home/ubuntu/.pyenv/versions/3.6.10/lib/python3.6/site-packages/django/db/models/query.py", line 57, in __iter__
    results = compiler.execute_sql(chunked_fetch=self.chunked_fetch, chunk_size=self.chunk_size)
  File "/home/ubuntu/.pyenv/versions/3.6.10/lib/python3.6/site-packages/django/db/models/sql/compiler.py", line 1137, in execute_sql
    cursor.execute(sql, params)
  File "/home/ubuntu/.pyenv/versions/3.6.10/lib/python3.6/site-packages/django/db/backends/utils.py", line 100, in execute
    return super().execute(sql, params)
  File "/home/ubuntu/.pyenv/versions/3.6.10/lib/python3.6/site-packages/django/db/backends/utils.py", line 68, in execute
    return self._execute_with_wrappers(sql, params, many=False, executor=self._execute)
  File "/home/ubuntu/.pyenv/versions/3.6.10/lib/python3.6/site-packages/django/db/backends/utils.py", line 77, in _execute_with_wrappers
    return executor(sql, params, many, context)
  File "/home/ubuntu/.pyenv/versions/3.6.10/lib/python3.6/site-packages/django/db/backends/utils.py", line 86, in _execute
    return self.cursor.execute(sql, params)
  File "/home/ubuntu/.pyenv/versions/3.6.10/lib/python3.6/site-packages/django/db/utils.py", line 90, in __exit__
    raise dj_exc_value.with_traceback(traceback) from exc_value
  File "/home/ubuntu/.pyenv/versions/3.6.10/lib/python3.6/site-packages/django/db/backends/utils.py", line 86, in _execute
    return self.cursor.execute(sql, params)
  File "/home/ubuntu/.pyenv/versions/3.6.10/lib/python3.6/site-packages/django/db/backends/mysql/base.py", line 74, in execute
    return self.cursor.execute(query, args)
  File "/home/ubuntu/.pyenv/versions/3.6.10/lib/python3.6/site-packages/pymysql/cursors.py", line 163, in execute
    result = self._query(query)
  File "/home/ubuntu/.pyenv/versions/3.6.10/lib/python3.6/site-packages/pymysql/cursors.py", line 321, in _query
    conn.query(q)
  File "/home/ubuntu/.pyenv/versions/3.6.10/lib/python3.6/site-packages/pymysql/connections.py", line 505, in query
    self._affected_rows = self._read_query_result(unbuffered=unbuffered)
  File "/home/ubuntu/.pyenv/versions/3.6.10/lib/python3.6/site-packages/pymysql/connections.py", line 724, in _read_query_result
    result.read()
  File "/home/ubuntu/.pyenv/versions/3.6.10/lib/python3.6/site-packages/pymysql/connections.py", line 1069, in read
    first_packet = self.connection._read_packet()
  File "/home/ubuntu/.pyenv/versions/3.6.10/lib/python3.6/site-packages/pymysql/connections.py", line 676, in _read_packet
    packet.raise_for_error()
  File "/home/ubuntu/.pyenv/versions/3.6.10/lib/python3.6/site-packages/pymysql/protocol.py", line 223, in raise_for_error
    err.raise_mysql_exception(self._data)
  File "/home/ubuntu/.pyenv/versions/3.6.10/lib/python3.6/site-packages/pymysql/err.py", line 107, in raise_mysql_exception
    raise errorclass(errno, errval)
django.db.utils.OperationalError: (1054, "Unknown column 'FACILITY_TB.CONTACT_NUMBER' in 'field list'")
[01/Sep/2020 15:35:16] ERROR [django.request:228] Internal Server Error: /facility/
Traceback (most recent call last):
  File "/home/ubuntu/.pyenv/versions/3.6.10/lib/python3.6/site-packages/django/db/backends/utils.py", line 86, in _execute
    return self.cursor.execute(sql, params)
  File "/home/ubuntu/.pyenv/versions/3.6.10/lib/python3.6/site-packages/django/db/backends/mysql/base.py", line 74, in execute
    return self.cursor.execute(query, args)
  File "/home/ubuntu/.pyenv/versions/3.6.10/lib/python3.6/site-packages/pymysql/cursors.py", line 163, in execute
    result = self._query(query)
  File "/home/ubuntu/.pyenv/versions/3.6.10/lib/python3.6/site-packages/pymysql/cursors.py", line 321, in _query
    conn.query(q)
  File "/home/ubuntu/.pyenv/versions/3.6.10/lib/python3.6/site-packages/pymysql/connections.py", line 505, in query
    self._affected_rows = self._read_query_result(unbuffered=unbuffered)
  File "/home/ubuntu/.pyenv/versions/3.6.10/lib/python3.6/site-packages/pymysql/connections.py", line 724, in _read_query_result
    result.read()
  File "/home/ubuntu/.pyenv/versions/3.6.10/lib/python3.6/site-packages/pymysql/connections.py", line 1069, in read
    first_packet = self.connection._read_packet()
  File "/home/ubuntu/.pyenv/versions/3.6.10/lib/python3.6/site-packages/pymysql/connections.py", line 676, in _read_packet
    packet.raise_for_error()
  File "/home/ubuntu/.pyenv/versions/3.6.10/lib/python3.6/site-packages/pymysql/protocol.py", line 223, in raise_for_error
    err.raise_mysql_exception(self._data)
  File "/home/ubuntu/.pyenv/versions/3.6.10/lib/python3.6/site-packages/pymysql/err.py", line 107, in raise_mysql_exception
    raise errorclass(errno, errval)
pymysql.err.OperationalError: (1054, "Unknown column 'FACILITY_TB.CONTACT_NUMBER' in 'field list'")

The above exception was the direct cause of the following exception:

Traceback (most recent call last):
  File "/home/ubuntu/.pyenv/versions/3.6.10/lib/python3.6/site-packages/django/core/handlers/exception.py", line 34, in inner
    response = get_response(request)
  File "/home/ubuntu/.pyenv/versions/3.6.10/lib/python3.6/site-packages/django/core/handlers/base.py", line 115, in _get_response
    response = self.process_exception_by_middleware(e, request)
  File "/home/ubuntu/.pyenv/versions/3.6.10/lib/python3.6/site-packages/django/core/handlers/base.py", line 113, in _get_response
    response = wrapped_callback(request, *callback_args, **callback_kwargs)
  File "/home/ubuntu/.pyenv/versions/3.6.10/lib/python3.6/site-packages/django/views/decorators/csrf.py", line 54, in wrapped_view
    return view_func(*args, **kwargs)
  File "/home/ubuntu/.pyenv/versions/3.6.10/lib/python3.6/site-packages/rest_framework/viewsets.py", line 114, in view
    return self.dispatch(request, *args, **kwargs)
  File "/home/ubuntu/.pyenv/versions/3.6.10/lib/python3.6/site-packages/rest_framework/views.py", line 505, in dispatch
    response = self.handle_exception(exc)
  File "/home/ubuntu/.pyenv/versions/3.6.10/lib/python3.6/site-packages/rest_framework/views.py", line 465, in handle_exception
    self.raise_uncaught_exception(exc)
  File "/home/ubuntu/.pyenv/versions/3.6.10/lib/python3.6/site-packages/rest_framework/views.py", line 476, in raise_uncaught_exception
    raise exc
  File "/home/ubuntu/.pyenv/versions/3.6.10/lib/python3.6/site-packages/rest_framework/views.py", line 502, in dispatch
    response = handler(request, *args, **kwargs)
  File "/home/ubuntu/.pyenv/versions/3.6.10/lib/python3.6/site-packages/rest_framework/mixins.py", line 40, in list
    page = self.paginate_queryset(queryset)
  File "/home/ubuntu/.pyenv/versions/3.6.10/lib/python3.6/site-packages/rest_framework/generics.py", line 171, in paginate_queryset
    return self.paginator.paginate_queryset(queryset, self.request, view=self)
  File "/home/ubuntu/.pyenv/versions/3.6.10/lib/python3.6/site-packages/rest_framework/pagination.py", line 218, in paginate_queryset
    return list(self.page)
  File "/home/ubuntu/.pyenv/versions/3.6.10/lib/python3.6/site-packages/django/core/paginator.py", line 150, in __len__
    return len(self.object_list)
  File "/home/ubuntu/.pyenv/versions/3.6.10/lib/python3.6/site-packages/django/db/models/query.py", line 258, in __len__
    self._fetch_all()
  File "/home/ubuntu/.pyenv/versions/3.6.10/lib/python3.6/site-packages/django/db/models/query.py", line 1261, in _fetch_all
    self._result_cache = list(self._iterable_class(self))
  File "/home/ubuntu/.pyenv/versions/3.6.10/lib/python3.6/site-packages/django/db/models/query.py", line 57, in __iter__
    results = compiler.execute_sql(chunked_fetch=self.chunked_fetch, chunk_size=self.chunk_size)
  File "/home/ubuntu/.pyenv/versions/3.6.10/lib/python3.6/site-packages/django/db/models/sql/compiler.py", line 1137, in execute_sql
    cursor.execute(sql, params)
  File "/home/ubuntu/.pyenv/versions/3.6.10/lib/python3.6/site-packages/django/db/backends/utils.py", line 100, in execute
    return super().execute(sql, params)
  File "/home/ubuntu/.pyenv/versions/3.6.10/lib/python3.6/site-packages/django/db/backends/utils.py", line 68, in execute
    return self._execute_with_wrappers(sql, params, many=False, executor=self._execute)
  File "/home/ubuntu/.pyenv/versions/3.6.10/lib/python3.6/site-packages/django/db/backends/utils.py", line 77, in _execute_with_wrappers
    return executor(sql, params, many, context)
  File "/home/ubuntu/.pyenv/versions/3.6.10/lib/python3.6/site-packages/django/db/backends/utils.py", line 86, in _execute
    return self.cursor.execute(sql, params)
  File "/home/ubuntu/.pyenv/versions/3.6.10/lib/python3.6/site-packages/django/db/utils.py", line 90, in __exit__
    raise dj_exc_value.with_traceback(traceback) from exc_value
  File "/home/ubuntu/.pyenv/versions/3.6.10/lib/python3.6/site-packages/django/db/backends/utils.py", line 86, in _execute
    return self.cursor.execute(sql, params)
  File "/home/ubuntu/.pyenv/versions/3.6.10/lib/python3.6/site-packages/django/db/backends/mysql/base.py", line 74, in execute
    return self.cursor.execute(query, args)
  File "/home/ubuntu/.pyenv/versions/3.6.10/lib/python3.6/site-packages/pymysql/cursors.py", line 163, in execute
    result = self._query(query)
  File "/home/ubuntu/.pyenv/versions/3.6.10/lib/python3.6/site-packages/pymysql/cursors.py", line 321, in _query
    conn.query(q)
  File "/home/ubuntu/.pyenv/versions/3.6.10/lib/python3.6/site-packages/pymysql/connections.py", line 505, in query
    self._affected_rows = self._read_query_result(unbuffered=unbuffered)
  File "/home/ubuntu/.pyenv/versions/3.6.10/lib/python3.6/site-packages/pymysql/connections.py", line 724, in _read_query_result
    result.read()
  File "/home/ubuntu/.pyenv/versions/3.6.10/lib/python3.6/site-packages/pymysql/connections.py", line 1069, in read
    first_packet = self.connection._read_packet()
  File "/home/ubuntu/.pyenv/versions/3.6.10/lib/python3.6/site-packages/pymysql/connections.py", line 676, in _read_packet
    packet.raise_for_error()
  File "/home/ubuntu/.pyenv/versions/3.6.10/lib/python3.6/site-packages/pymysql/protocol.py", line 223, in raise_for_error
    err.raise_mysql_exception(self._data)
  File "/home/ubuntu/.pyenv/versions/3.6.10/lib/python3.6/site-packages/pymysql/err.py", line 107, in raise_mysql_exception
    raise errorclass(errno, errval)
django.db.utils.OperationalError: (1054, "Unknown column 'FACILITY_TB.CONTACT_NUMBER' in 'field list'")
[01/Sep/2020 15:36:09] ERROR [django.request:228] Internal Server Error: /facility/
Traceback (most recent call last):
  File "/home/ubuntu/.pyenv/versions/3.6.10/lib/python3.6/site-packages/django/db/backends/utils.py", line 86, in _execute
    return self.cursor.execute(sql, params)
  File "/home/ubuntu/.pyenv/versions/3.6.10/lib/python3.6/site-packages/django/db/backends/mysql/base.py", line 74, in execute
    return self.cursor.execute(query, args)
  File "/home/ubuntu/.pyenv/versions/3.6.10/lib/python3.6/site-packages/pymysql/cursors.py", line 163, in execute
    result = self._query(query)
  File "/home/ubuntu/.pyenv/versions/3.6.10/lib/python3.6/site-packages/pymysql/cursors.py", line 321, in _query
    conn.query(q)
  File "/home/ubuntu/.pyenv/versions/3.6.10/lib/python3.6/site-packages/pymysql/connections.py", line 505, in query
    self._affected_rows = self._read_query_result(unbuffered=unbuffered)
  File "/home/ubuntu/.pyenv/versions/3.6.10/lib/python3.6/site-packages/pymysql/connections.py", line 724, in _read_query_result
    result.read()
  File "/home/ubuntu/.pyenv/versions/3.6.10/lib/python3.6/site-packages/pymysql/connections.py", line 1069, in read
    first_packet = self.connection._read_packet()
  File "/home/ubuntu/.pyenv/versions/3.6.10/lib/python3.6/site-packages/pymysql/connections.py", line 676, in _read_packet
    packet.raise_for_error()
  File "/home/ubuntu/.pyenv/versions/3.6.10/lib/python3.6/site-packages/pymysql/protocol.py", line 223, in raise_for_error
    err.raise_mysql_exception(self._data)
  File "/home/ubuntu/.pyenv/versions/3.6.10/lib/python3.6/site-packages/pymysql/err.py", line 107, in raise_mysql_exception
    raise errorclass(errno, errval)
pymysql.err.OperationalError: (1054, "Unknown column 'FACILITY_TB.CONTACT_NUMBER' in 'field list'")

The above exception was the direct cause of the following exception:

Traceback (most recent call last):
  File "/home/ubuntu/.pyenv/versions/3.6.10/lib/python3.6/site-packages/django/core/handlers/exception.py", line 34, in inner
    response = get_response(request)
  File "/home/ubuntu/.pyenv/versions/3.6.10/lib/python3.6/site-packages/django/core/handlers/base.py", line 115, in _get_response
    response = self.process_exception_by_middleware(e, request)
  File "/home/ubuntu/.pyenv/versions/3.6.10/lib/python3.6/site-packages/django/core/handlers/base.py", line 113, in _get_response
    response = wrapped_callback(request, *callback_args, **callback_kwargs)
  File "/home/ubuntu/.pyenv/versions/3.6.10/lib/python3.6/site-packages/django/views/decorators/csrf.py", line 54, in wrapped_view
    return view_func(*args, **kwargs)
  File "/home/ubuntu/.pyenv/versions/3.6.10/lib/python3.6/site-packages/rest_framework/viewsets.py", line 114, in view
    return self.dispatch(request, *args, **kwargs)
  File "/home/ubuntu/.pyenv/versions/3.6.10/lib/python3.6/site-packages/rest_framework/views.py", line 505, in dispatch
    response = self.handle_exception(exc)
  File "/home/ubuntu/.pyenv/versions/3.6.10/lib/python3.6/site-packages/rest_framework/views.py", line 465, in handle_exception
    self.raise_uncaught_exception(exc)
  File "/home/ubuntu/.pyenv/versions/3.6.10/lib/python3.6/site-packages/rest_framework/views.py", line 476, in raise_uncaught_exception
    raise exc
  File "/home/ubuntu/.pyenv/versions/3.6.10/lib/python3.6/site-packages/rest_framework/views.py", line 502, in dispatch
    response = handler(request, *args, **kwargs)
  File "/home/ubuntu/.pyenv/versions/3.6.10/lib/python3.6/site-packages/rest_framework/mixins.py", line 40, in list
    page = self.paginate_queryset(queryset)
  File "/home/ubuntu/.pyenv/versions/3.6.10/lib/python3.6/site-packages/rest_framework/generics.py", line 171, in paginate_queryset
    return self.paginator.paginate_queryset(queryset, self.request, view=self)
  File "/home/ubuntu/.pyenv/versions/3.6.10/lib/python3.6/site-packages/rest_framework/pagination.py", line 218, in paginate_queryset
    return list(self.page)
  File "/home/ubuntu/.pyenv/versions/3.6.10/lib/python3.6/site-packages/django/core/paginator.py", line 150, in __len__
    return len(self.object_list)
  File "/home/ubuntu/.pyenv/versions/3.6.10/lib/python3.6/site-packages/django/db/models/query.py", line 258, in __len__
    self._fetch_all()
  File "/home/ubuntu/.pyenv/versions/3.6.10/lib/python3.6/site-packages/django/db/models/query.py", line 1261, in _fetch_all
    self._result_cache = list(self._iterable_class(self))
  File "/home/ubuntu/.pyenv/versions/3.6.10/lib/python3.6/site-packages/django/db/models/query.py", line 57, in __iter__
    results = compiler.execute_sql(chunked_fetch=self.chunked_fetch, chunk_size=self.chunk_size)
  File "/home/ubuntu/.pyenv/versions/3.6.10/lib/python3.6/site-packages/django/db/models/sql/compiler.py", line 1137, in execute_sql
    cursor.execute(sql, params)
  File "/home/ubuntu/.pyenv/versions/3.6.10/lib/python3.6/site-packages/django/db/backends/utils.py", line 100, in execute
    return super().execute(sql, params)
  File "/home/ubuntu/.pyenv/versions/3.6.10/lib/python3.6/site-packages/django/db/backends/utils.py", line 68, in execute
    return self._execute_with_wrappers(sql, params, many=False, executor=self._execute)
  File "/home/ubuntu/.pyenv/versions/3.6.10/lib/python3.6/site-packages/django/db/backends/utils.py", line 77, in _execute_with_wrappers
    return executor(sql, params, many, context)
  File "/home/ubuntu/.pyenv/versions/3.6.10/lib/python3.6/site-packages/django/db/backends/utils.py", line 86, in _execute
    return self.cursor.execute(sql, params)
  File "/home/ubuntu/.pyenv/versions/3.6.10/lib/python3.6/site-packages/django/db/utils.py", line 90, in __exit__
    raise dj_exc_value.with_traceback(traceback) from exc_value
  File "/home/ubuntu/.pyenv/versions/3.6.10/lib/python3.6/site-packages/django/db/backends/utils.py", line 86, in _execute
    return self.cursor.execute(sql, params)
  File "/home/ubuntu/.pyenv/versions/3.6.10/lib/python3.6/site-packages/django/db/backends/mysql/base.py", line 74, in execute
    return self.cursor.execute(query, args)
  File "/home/ubuntu/.pyenv/versions/3.6.10/lib/python3.6/site-packages/pymysql/cursors.py", line 163, in execute
    result = self._query(query)
  File "/home/ubuntu/.pyenv/versions/3.6.10/lib/python3.6/site-packages/pymysql/cursors.py", line 321, in _query
    conn.query(q)
  File "/home/ubuntu/.pyenv/versions/3.6.10/lib/python3.6/site-packages/pymysql/connections.py", line 505, in query
    self._affected_rows = self._read_query_result(unbuffered=unbuffered)
  File "/home/ubuntu/.pyenv/versions/3.6.10/lib/python3.6/site-packages/pymysql/connections.py", line 724, in _read_query_result
    result.read()
  File "/home/ubuntu/.pyenv/versions/3.6.10/lib/python3.6/site-packages/pymysql/connections.py", line 1069, in read
    first_packet = self.connection._read_packet()
  File "/home/ubuntu/.pyenv/versions/3.6.10/lib/python3.6/site-packages/pymysql/connections.py", line 676, in _read_packet
    packet.raise_for_error()
  File "/home/ubuntu/.pyenv/versions/3.6.10/lib/python3.6/site-packages/pymysql/protocol.py", line 223, in raise_for_error
    err.raise_mysql_exception(self._data)
  File "/home/ubuntu/.pyenv/versions/3.6.10/lib/python3.6/site-packages/pymysql/err.py", line 107, in raise_mysql_exception
    raise errorclass(errno, errval)
django.db.utils.OperationalError: (1054, "Unknown column 'FACILITY_TB.CONTACT_NUMBER' in 'field list'")
[01/Sep/2020 15:36:42] ERROR [django.request:228] Internal Server Error: /facility/
Traceback (most recent call last):
  File "/home/ubuntu/.pyenv/versions/3.6.10/lib/python3.6/site-packages/django/db/backends/utils.py", line 86, in _execute
    return self.cursor.execute(sql, params)
  File "/home/ubuntu/.pyenv/versions/3.6.10/lib/python3.6/site-packages/django/db/backends/mysql/base.py", line 74, in execute
    return self.cursor.execute(query, args)
  File "/home/ubuntu/.pyenv/versions/3.6.10/lib/python3.6/site-packages/pymysql/cursors.py", line 163, in execute
    result = self._query(query)
  File "/home/ubuntu/.pyenv/versions/3.6.10/lib/python3.6/site-packages/pymysql/cursors.py", line 321, in _query
    conn.query(q)
  File "/home/ubuntu/.pyenv/versions/3.6.10/lib/python3.6/site-packages/pymysql/connections.py", line 505, in query
    self._affected_rows = self._read_query_result(unbuffered=unbuffered)
  File "/home/ubuntu/.pyenv/versions/3.6.10/lib/python3.6/site-packages/pymysql/connections.py", line 724, in _read_query_result
    result.read()
  File "/home/ubuntu/.pyenv/versions/3.6.10/lib/python3.6/site-packages/pymysql/connections.py", line 1069, in read
    first_packet = self.connection._read_packet()
  File "/home/ubuntu/.pyenv/versions/3.6.10/lib/python3.6/site-packages/pymysql/connections.py", line 676, in _read_packet
    packet.raise_for_error()
  File "/home/ubuntu/.pyenv/versions/3.6.10/lib/python3.6/site-packages/pymysql/protocol.py", line 223, in raise_for_error
    err.raise_mysql_exception(self._data)
  File "/home/ubuntu/.pyenv/versions/3.6.10/lib/python3.6/site-packages/pymysql/err.py", line 107, in raise_mysql_exception
    raise errorclass(errno, errval)
pymysql.err.OperationalError: (1054, "Unknown column 'FACILITY_TB.CONTACT_NUMBER' in 'field list'")

The above exception was the direct cause of the following exception:

Traceback (most recent call last):
  File "/home/ubuntu/.pyenv/versions/3.6.10/lib/python3.6/site-packages/django/core/handlers/exception.py", line 34, in inner
    response = get_response(request)
  File "/home/ubuntu/.pyenv/versions/3.6.10/lib/python3.6/site-packages/django/core/handlers/base.py", line 115, in _get_response
    response = self.process_exception_by_middleware(e, request)
  File "/home/ubuntu/.pyenv/versions/3.6.10/lib/python3.6/site-packages/django/core/handlers/base.py", line 113, in _get_response
    response = wrapped_callback(request, *callback_args, **callback_kwargs)
  File "/home/ubuntu/.pyenv/versions/3.6.10/lib/python3.6/site-packages/django/views/decorators/csrf.py", line 54, in wrapped_view
    return view_func(*args, **kwargs)
  File "/home/ubuntu/.pyenv/versions/3.6.10/lib/python3.6/site-packages/rest_framework/viewsets.py", line 114, in view
    return self.dispatch(request, *args, **kwargs)
  File "/home/ubuntu/.pyenv/versions/3.6.10/lib/python3.6/site-packages/rest_framework/views.py", line 505, in dispatch
    response = self.handle_exception(exc)
  File "/home/ubuntu/.pyenv/versions/3.6.10/lib/python3.6/site-packages/rest_framework/views.py", line 465, in handle_exception
    self.raise_uncaught_exception(exc)
  File "/home/ubuntu/.pyenv/versions/3.6.10/lib/python3.6/site-packages/rest_framework/views.py", line 476, in raise_uncaught_exception
    raise exc
  File "/home/ubuntu/.pyenv/versions/3.6.10/lib/python3.6/site-packages/rest_framework/views.py", line 502, in dispatch
    response = handler(request, *args, **kwargs)
  File "/home/ubuntu/.pyenv/versions/3.6.10/lib/python3.6/site-packages/rest_framework/mixins.py", line 40, in list
    page = self.paginate_queryset(queryset)
  File "/home/ubuntu/.pyenv/versions/3.6.10/lib/python3.6/site-packages/rest_framework/generics.py", line 171, in paginate_queryset
    return self.paginator.paginate_queryset(queryset, self.request, view=self)
  File "/home/ubuntu/.pyenv/versions/3.6.10/lib/python3.6/site-packages/rest_framework/pagination.py", line 218, in paginate_queryset
    return list(self.page)
  File "/home/ubuntu/.pyenv/versions/3.6.10/lib/python3.6/site-packages/django/core/paginator.py", line 150, in __len__
    return len(self.object_list)
  File "/home/ubuntu/.pyenv/versions/3.6.10/lib/python3.6/site-packages/django/db/models/query.py", line 258, in __len__
    self._fetch_all()
  File "/home/ubuntu/.pyenv/versions/3.6.10/lib/python3.6/site-packages/django/db/models/query.py", line 1261, in _fetch_all
    self._result_cache = list(self._iterable_class(self))
  File "/home/ubuntu/.pyenv/versions/3.6.10/lib/python3.6/site-packages/django/db/models/query.py", line 57, in __iter__
    results = compiler.execute_sql(chunked_fetch=self.chunked_fetch, chunk_size=self.chunk_size)
  File "/home/ubuntu/.pyenv/versions/3.6.10/lib/python3.6/site-packages/django/db/models/sql/compiler.py", line 1137, in execute_sql
    cursor.execute(sql, params)
  File "/home/ubuntu/.pyenv/versions/3.6.10/lib/python3.6/site-packages/django/db/backends/utils.py", line 100, in execute
    return super().execute(sql, params)
  File "/home/ubuntu/.pyenv/versions/3.6.10/lib/python3.6/site-packages/django/db/backends/utils.py", line 68, in execute
    return self._execute_with_wrappers(sql, params, many=False, executor=self._execute)
  File "/home/ubuntu/.pyenv/versions/3.6.10/lib/python3.6/site-packages/django/db/backends/utils.py", line 77, in _execute_with_wrappers
    return executor(sql, params, many, context)
  File "/home/ubuntu/.pyenv/versions/3.6.10/lib/python3.6/site-packages/django/db/backends/utils.py", line 86, in _execute
    return self.cursor.execute(sql, params)
  File "/home/ubuntu/.pyenv/versions/3.6.10/lib/python3.6/site-packages/django/db/utils.py", line 90, in __exit__
    raise dj_exc_value.with_traceback(traceback) from exc_value
  File "/home/ubuntu/.pyenv/versions/3.6.10/lib/python3.6/site-packages/django/db/backends/utils.py", line 86, in _execute
    return self.cursor.execute(sql, params)
  File "/home/ubuntu/.pyenv/versions/3.6.10/lib/python3.6/site-packages/django/db/backends/mysql/base.py", line 74, in execute
    return self.cursor.execute(query, args)
  File "/home/ubuntu/.pyenv/versions/3.6.10/lib/python3.6/site-packages/pymysql/cursors.py", line 163, in execute
    result = self._query(query)
  File "/home/ubuntu/.pyenv/versions/3.6.10/lib/python3.6/site-packages/pymysql/cursors.py", line 321, in _query
    conn.query(q)
  File "/home/ubuntu/.pyenv/versions/3.6.10/lib/python3.6/site-packages/pymysql/connections.py", line 505, in query
    self._affected_rows = self._read_query_result(unbuffered=unbuffered)
  File "/home/ubuntu/.pyenv/versions/3.6.10/lib/python3.6/site-packages/pymysql/connections.py", line 724, in _read_query_result
    result.read()
  File "/home/ubuntu/.pyenv/versions/3.6.10/lib/python3.6/site-packages/pymysql/connections.py", line 1069, in read
    first_packet = self.connection._read_packet()
  File "/home/ubuntu/.pyenv/versions/3.6.10/lib/python3.6/site-packages/pymysql/connections.py", line 676, in _read_packet
    packet.raise_for_error()
  File "/home/ubuntu/.pyenv/versions/3.6.10/lib/python3.6/site-packages/pymysql/protocol.py", line 223, in raise_for_error
    err.raise_mysql_exception(self._data)
  File "/home/ubuntu/.pyenv/versions/3.6.10/lib/python3.6/site-packages/pymysql/err.py", line 107, in raise_mysql_exception
    raise errorclass(errno, errval)
django.db.utils.OperationalError: (1054, "Unknown column 'FACILITY_TB.CONTACT_NUMBER' in 'field list'")
[01/Sep/2020 15:36:50] ERROR [django.request:228] Internal Server Error: /facility/
Traceback (most recent call last):
  File "/home/ubuntu/.pyenv/versions/3.6.10/lib/python3.6/site-packages/django/db/backends/utils.py", line 86, in _execute
    return self.cursor.execute(sql, params)
  File "/home/ubuntu/.pyenv/versions/3.6.10/lib/python3.6/site-packages/django/db/backends/mysql/base.py", line 74, in execute
    return self.cursor.execute(query, args)
  File "/home/ubuntu/.pyenv/versions/3.6.10/lib/python3.6/site-packages/pymysql/cursors.py", line 163, in execute
    result = self._query(query)
  File "/home/ubuntu/.pyenv/versions/3.6.10/lib/python3.6/site-packages/pymysql/cursors.py", line 321, in _query
    conn.query(q)
  File "/home/ubuntu/.pyenv/versions/3.6.10/lib/python3.6/site-packages/pymysql/connections.py", line 505, in query
    self._affected_rows = self._read_query_result(unbuffered=unbuffered)
  File "/home/ubuntu/.pyenv/versions/3.6.10/lib/python3.6/site-packages/pymysql/connections.py", line 724, in _read_query_result
    result.read()
  File "/home/ubuntu/.pyenv/versions/3.6.10/lib/python3.6/site-packages/pymysql/connections.py", line 1069, in read
    first_packet = self.connection._read_packet()
  File "/home/ubuntu/.pyenv/versions/3.6.10/lib/python3.6/site-packages/pymysql/connections.py", line 676, in _read_packet
    packet.raise_for_error()
  File "/home/ubuntu/.pyenv/versions/3.6.10/lib/python3.6/site-packages/pymysql/protocol.py", line 223, in raise_for_error
    err.raise_mysql_exception(self._data)
  File "/home/ubuntu/.pyenv/versions/3.6.10/lib/python3.6/site-packages/pymysql/err.py", line 107, in raise_mysql_exception
    raise errorclass(errno, errval)
pymysql.err.OperationalError: (1054, "Unknown column 'FACILITY_TB.CONTACT_NUMBER' in 'field list'")

The above exception was the direct cause of the following exception:

Traceback (most recent call last):
  File "/home/ubuntu/.pyenv/versions/3.6.10/lib/python3.6/site-packages/django/core/handlers/exception.py", line 34, in inner
    response = get_response(request)
  File "/home/ubuntu/.pyenv/versions/3.6.10/lib/python3.6/site-packages/django/core/handlers/base.py", line 115, in _get_response
    response = self.process_exception_by_middleware(e, request)
  File "/home/ubuntu/.pyenv/versions/3.6.10/lib/python3.6/site-packages/django/core/handlers/base.py", line 113, in _get_response
    response = wrapped_callback(request, *callback_args, **callback_kwargs)
  File "/home/ubuntu/.pyenv/versions/3.6.10/lib/python3.6/site-packages/django/views/decorators/csrf.py", line 54, in wrapped_view
    return view_func(*args, **kwargs)
  File "/home/ubuntu/.pyenv/versions/3.6.10/lib/python3.6/site-packages/rest_framework/viewsets.py", line 114, in view
    return self.dispatch(request, *args, **kwargs)
  File "/home/ubuntu/.pyenv/versions/3.6.10/lib/python3.6/site-packages/rest_framework/views.py", line 505, in dispatch
    response = self.handle_exception(exc)
  File "/home/ubuntu/.pyenv/versions/3.6.10/lib/python3.6/site-packages/rest_framework/views.py", line 465, in handle_exception
    self.raise_uncaught_exception(exc)
  File "/home/ubuntu/.pyenv/versions/3.6.10/lib/python3.6/site-packages/rest_framework/views.py", line 476, in raise_uncaught_exception
    raise exc
  File "/home/ubuntu/.pyenv/versions/3.6.10/lib/python3.6/site-packages/rest_framework/views.py", line 502, in dispatch
    response = handler(request, *args, **kwargs)
  File "/home/ubuntu/.pyenv/versions/3.6.10/lib/python3.6/site-packages/rest_framework/mixins.py", line 40, in list
    page = self.paginate_queryset(queryset)
  File "/home/ubuntu/.pyenv/versions/3.6.10/lib/python3.6/site-packages/rest_framework/generics.py", line 171, in paginate_queryset
    return self.paginator.paginate_queryset(queryset, self.request, view=self)
  File "/home/ubuntu/.pyenv/versions/3.6.10/lib/python3.6/site-packages/rest_framework/pagination.py", line 218, in paginate_queryset
    return list(self.page)
  File "/home/ubuntu/.pyenv/versions/3.6.10/lib/python3.6/site-packages/django/core/paginator.py", line 150, in __len__
    return len(self.object_list)
  File "/home/ubuntu/.pyenv/versions/3.6.10/lib/python3.6/site-packages/django/db/models/query.py", line 258, in __len__
    self._fetch_all()
  File "/home/ubuntu/.pyenv/versions/3.6.10/lib/python3.6/site-packages/django/db/models/query.py", line 1261, in _fetch_all
    self._result_cache = list(self._iterable_class(self))
  File "/home/ubuntu/.pyenv/versions/3.6.10/lib/python3.6/site-packages/django/db/models/query.py", line 57, in __iter__
    results = compiler.execute_sql(chunked_fetch=self.chunked_fetch, chunk_size=self.chunk_size)
  File "/home/ubuntu/.pyenv/versions/3.6.10/lib/python3.6/site-packages/django/db/models/sql/compiler.py", line 1137, in execute_sql
    cursor.execute(sql, params)
  File "/home/ubuntu/.pyenv/versions/3.6.10/lib/python3.6/site-packages/django/db/backends/utils.py", line 100, in execute
    return super().execute(sql, params)
  File "/home/ubuntu/.pyenv/versions/3.6.10/lib/python3.6/site-packages/django/db/backends/utils.py", line 68, in execute
    return self._execute_with_wrappers(sql, params, many=False, executor=self._execute)
  File "/home/ubuntu/.pyenv/versions/3.6.10/lib/python3.6/site-packages/django/db/backends/utils.py", line 77, in _execute_with_wrappers
    return executor(sql, params, many, context)
  File "/home/ubuntu/.pyenv/versions/3.6.10/lib/python3.6/site-packages/django/db/backends/utils.py", line 86, in _execute
    return self.cursor.execute(sql, params)
  File "/home/ubuntu/.pyenv/versions/3.6.10/lib/python3.6/site-packages/django/db/utils.py", line 90, in __exit__
    raise dj_exc_value.with_traceback(traceback) from exc_value
  File "/home/ubuntu/.pyenv/versions/3.6.10/lib/python3.6/site-packages/django/db/backends/utils.py", line 86, in _execute
    return self.cursor.execute(sql, params)
  File "/home/ubuntu/.pyenv/versions/3.6.10/lib/python3.6/site-packages/django/db/backends/mysql/base.py", line 74, in execute
    return self.cursor.execute(query, args)
  File "/home/ubuntu/.pyenv/versions/3.6.10/lib/python3.6/site-packages/pymysql/cursors.py", line 163, in execute
    result = self._query(query)
  File "/home/ubuntu/.pyenv/versions/3.6.10/lib/python3.6/site-packages/pymysql/cursors.py", line 321, in _query
    conn.query(q)
  File "/home/ubuntu/.pyenv/versions/3.6.10/lib/python3.6/site-packages/pymysql/connections.py", line 505, in query
    self._affected_rows = self._read_query_result(unbuffered=unbuffered)
  File "/home/ubuntu/.pyenv/versions/3.6.10/lib/python3.6/site-packages/pymysql/connections.py", line 724, in _read_query_result
    result.read()
  File "/home/ubuntu/.pyenv/versions/3.6.10/lib/python3.6/site-packages/pymysql/connections.py", line 1069, in read
    first_packet = self.connection._read_packet()
  File "/home/ubuntu/.pyenv/versions/3.6.10/lib/python3.6/site-packages/pymysql/connections.py", line 676, in _read_packet
    packet.raise_for_error()
  File "/home/ubuntu/.pyenv/versions/3.6.10/lib/python3.6/site-packages/pymysql/protocol.py", line 223, in raise_for_error
    err.raise_mysql_exception(self._data)
  File "/home/ubuntu/.pyenv/versions/3.6.10/lib/python3.6/site-packages/pymysql/err.py", line 107, in raise_mysql_exception
    raise errorclass(errno, errval)
django.db.utils.OperationalError: (1054, "Unknown column 'FACILITY_TB.CONTACT_NUMBER' in 'field list'")
[01/Sep/2020 15:36:54] ERROR [django.request:228] Internal Server Error: /facility/
Traceback (most recent call last):
  File "/home/ubuntu/.pyenv/versions/3.6.10/lib/python3.6/site-packages/django/db/backends/utils.py", line 86, in _execute
    return self.cursor.execute(sql, params)
  File "/home/ubuntu/.pyenv/versions/3.6.10/lib/python3.6/site-packages/django/db/backends/mysql/base.py", line 74, in execute
    return self.cursor.execute(query, args)
  File "/home/ubuntu/.pyenv/versions/3.6.10/lib/python3.6/site-packages/pymysql/cursors.py", line 163, in execute
    result = self._query(query)
  File "/home/ubuntu/.pyenv/versions/3.6.10/lib/python3.6/site-packages/pymysql/cursors.py", line 321, in _query
    conn.query(q)
  File "/home/ubuntu/.pyenv/versions/3.6.10/lib/python3.6/site-packages/pymysql/connections.py", line 505, in query
    self._affected_rows = self._read_query_result(unbuffered=unbuffered)
  File "/home/ubuntu/.pyenv/versions/3.6.10/lib/python3.6/site-packages/pymysql/connections.py", line 724, in _read_query_result
    result.read()
  File "/home/ubuntu/.pyenv/versions/3.6.10/lib/python3.6/site-packages/pymysql/connections.py", line 1069, in read
    first_packet = self.connection._read_packet()
  File "/home/ubuntu/.pyenv/versions/3.6.10/lib/python3.6/site-packages/pymysql/connections.py", line 676, in _read_packet
    packet.raise_for_error()
  File "/home/ubuntu/.pyenv/versions/3.6.10/lib/python3.6/site-packages/pymysql/protocol.py", line 223, in raise_for_error
    err.raise_mysql_exception(self._data)
  File "/home/ubuntu/.pyenv/versions/3.6.10/lib/python3.6/site-packages/pymysql/err.py", line 107, in raise_mysql_exception
    raise errorclass(errno, errval)
pymysql.err.OperationalError: (1054, "Unknown column 'FACILITY_TB.CONTACT_NUMBER' in 'field list'")

The above exception was the direct cause of the following exception:

Traceback (most recent call last):
  File "/home/ubuntu/.pyenv/versions/3.6.10/lib/python3.6/site-packages/django/core/handlers/exception.py", line 34, in inner
    response = get_response(request)
  File "/home/ubuntu/.pyenv/versions/3.6.10/lib/python3.6/site-packages/django/core/handlers/base.py", line 115, in _get_response
    response = self.process_exception_by_middleware(e, request)
  File "/home/ubuntu/.pyenv/versions/3.6.10/lib/python3.6/site-packages/django/core/handlers/base.py", line 113, in _get_response
    response = wrapped_callback(request, *callback_args, **callback_kwargs)
  File "/home/ubuntu/.pyenv/versions/3.6.10/lib/python3.6/site-packages/django/views/decorators/csrf.py", line 54, in wrapped_view
    return view_func(*args, **kwargs)
  File "/home/ubuntu/.pyenv/versions/3.6.10/lib/python3.6/site-packages/rest_framework/viewsets.py", line 114, in view
    return self.dispatch(request, *args, **kwargs)
  File "/home/ubuntu/.pyenv/versions/3.6.10/lib/python3.6/site-packages/rest_framework/views.py", line 505, in dispatch
    response = self.handle_exception(exc)
  File "/home/ubuntu/.pyenv/versions/3.6.10/lib/python3.6/site-packages/rest_framework/views.py", line 465, in handle_exception
    self.raise_uncaught_exception(exc)
  File "/home/ubuntu/.pyenv/versions/3.6.10/lib/python3.6/site-packages/rest_framework/views.py", line 476, in raise_uncaught_exception
    raise exc
  File "/home/ubuntu/.pyenv/versions/3.6.10/lib/python3.6/site-packages/rest_framework/views.py", line 502, in dispatch
    response = handler(request, *args, **kwargs)
  File "/home/ubuntu/.pyenv/versions/3.6.10/lib/python3.6/site-packages/rest_framework/mixins.py", line 40, in list
    page = self.paginate_queryset(queryset)
  File "/home/ubuntu/.pyenv/versions/3.6.10/lib/python3.6/site-packages/rest_framework/generics.py", line 171, in paginate_queryset
    return self.paginator.paginate_queryset(queryset, self.request, view=self)
  File "/home/ubuntu/.pyenv/versions/3.6.10/lib/python3.6/site-packages/rest_framework/pagination.py", line 218, in paginate_queryset
    return list(self.page)
  File "/home/ubuntu/.pyenv/versions/3.6.10/lib/python3.6/site-packages/django/core/paginator.py", line 150, in __len__
    return len(self.object_list)
  File "/home/ubuntu/.pyenv/versions/3.6.10/lib/python3.6/site-packages/django/db/models/query.py", line 258, in __len__
    self._fetch_all()
  File "/home/ubuntu/.pyenv/versions/3.6.10/lib/python3.6/site-packages/django/db/models/query.py", line 1261, in _fetch_all
    self._result_cache = list(self._iterable_class(self))
  File "/home/ubuntu/.pyenv/versions/3.6.10/lib/python3.6/site-packages/django/db/models/query.py", line 57, in __iter__
    results = compiler.execute_sql(chunked_fetch=self.chunked_fetch, chunk_size=self.chunk_size)
  File "/home/ubuntu/.pyenv/versions/3.6.10/lib/python3.6/site-packages/django/db/models/sql/compiler.py", line 1137, in execute_sql
    cursor.execute(sql, params)
  File "/home/ubuntu/.pyenv/versions/3.6.10/lib/python3.6/site-packages/django/db/backends/utils.py", line 100, in execute
    return super().execute(sql, params)
  File "/home/ubuntu/.pyenv/versions/3.6.10/lib/python3.6/site-packages/django/db/backends/utils.py", line 68, in execute
    return self._execute_with_wrappers(sql, params, many=False, executor=self._execute)
  File "/home/ubuntu/.pyenv/versions/3.6.10/lib/python3.6/site-packages/django/db/backends/utils.py", line 77, in _execute_with_wrappers
    return executor(sql, params, many, context)
  File "/home/ubuntu/.pyenv/versions/3.6.10/lib/python3.6/site-packages/django/db/backends/utils.py", line 86, in _execute
    return self.cursor.execute(sql, params)
  File "/home/ubuntu/.pyenv/versions/3.6.10/lib/python3.6/site-packages/django/db/utils.py", line 90, in __exit__
    raise dj_exc_value.with_traceback(traceback) from exc_value
  File "/home/ubuntu/.pyenv/versions/3.6.10/lib/python3.6/site-packages/django/db/backends/utils.py", line 86, in _execute
    return self.cursor.execute(sql, params)
  File "/home/ubuntu/.pyenv/versions/3.6.10/lib/python3.6/site-packages/django/db/backends/mysql/base.py", line 74, in execute
    return self.cursor.execute(query, args)
  File "/home/ubuntu/.pyenv/versions/3.6.10/lib/python3.6/site-packages/pymysql/cursors.py", line 163, in execute
    result = self._query(query)
  File "/home/ubuntu/.pyenv/versions/3.6.10/lib/python3.6/site-packages/pymysql/cursors.py", line 321, in _query
    conn.query(q)
  File "/home/ubuntu/.pyenv/versions/3.6.10/lib/python3.6/site-packages/pymysql/connections.py", line 505, in query
    self._affected_rows = self._read_query_result(unbuffered=unbuffered)
  File "/home/ubuntu/.pyenv/versions/3.6.10/lib/python3.6/site-packages/pymysql/connections.py", line 724, in _read_query_result
    result.read()
  File "/home/ubuntu/.pyenv/versions/3.6.10/lib/python3.6/site-packages/pymysql/connections.py", line 1069, in read
    first_packet = self.connection._read_packet()
  File "/home/ubuntu/.pyenv/versions/3.6.10/lib/python3.6/site-packages/pymysql/connections.py", line 676, in _read_packet
    packet.raise_for_error()
  File "/home/ubuntu/.pyenv/versions/3.6.10/lib/python3.6/site-packages/pymysql/protocol.py", line 223, in raise_for_error
    err.raise_mysql_exception(self._data)
  File "/home/ubuntu/.pyenv/versions/3.6.10/lib/python3.6/site-packages/pymysql/err.py", line 107, in raise_mysql_exception
    raise errorclass(errno, errval)
django.db.utils.OperationalError: (1054, "Unknown column 'FACILITY_TB.CONTACT_NUMBER' in 'field list'")
[01/Sep/2020 15:36:59] ERROR [django.request:228] Internal Server Error: /facility/
Traceback (most recent call last):
  File "/home/ubuntu/.pyenv/versions/3.6.10/lib/python3.6/site-packages/django/db/backends/utils.py", line 86, in _execute
    return self.cursor.execute(sql, params)
  File "/home/ubuntu/.pyenv/versions/3.6.10/lib/python3.6/site-packages/django/db/backends/mysql/base.py", line 74, in execute
    return self.cursor.execute(query, args)
  File "/home/ubuntu/.pyenv/versions/3.6.10/lib/python3.6/site-packages/pymysql/cursors.py", line 163, in execute
    result = self._query(query)
  File "/home/ubuntu/.pyenv/versions/3.6.10/lib/python3.6/site-packages/pymysql/cursors.py", line 321, in _query
    conn.query(q)
  File "/home/ubuntu/.pyenv/versions/3.6.10/lib/python3.6/site-packages/pymysql/connections.py", line 505, in query
    self._affected_rows = self._read_query_result(unbuffered=unbuffered)
  File "/home/ubuntu/.pyenv/versions/3.6.10/lib/python3.6/site-packages/pymysql/connections.py", line 724, in _read_query_result
    result.read()
  File "/home/ubuntu/.pyenv/versions/3.6.10/lib/python3.6/site-packages/pymysql/connections.py", line 1069, in read
    first_packet = self.connection._read_packet()
  File "/home/ubuntu/.pyenv/versions/3.6.10/lib/python3.6/site-packages/pymysql/connections.py", line 676, in _read_packet
    packet.raise_for_error()
  File "/home/ubuntu/.pyenv/versions/3.6.10/lib/python3.6/site-packages/pymysql/protocol.py", line 223, in raise_for_error
    err.raise_mysql_exception(self._data)
  File "/home/ubuntu/.pyenv/versions/3.6.10/lib/python3.6/site-packages/pymysql/err.py", line 107, in raise_mysql_exception
    raise errorclass(errno, errval)
pymysql.err.OperationalError: (1054, "Unknown column 'FACILITY_TB.CONTACT_NUMBER' in 'field list'")

The above exception was the direct cause of the following exception:

Traceback (most recent call last):
  File "/home/ubuntu/.pyenv/versions/3.6.10/lib/python3.6/site-packages/django/core/handlers/exception.py", line 34, in inner
    response = get_response(request)
  File "/home/ubuntu/.pyenv/versions/3.6.10/lib/python3.6/site-packages/django/core/handlers/base.py", line 115, in _get_response
    response = self.process_exception_by_middleware(e, request)
  File "/home/ubuntu/.pyenv/versions/3.6.10/lib/python3.6/site-packages/django/core/handlers/base.py", line 113, in _get_response
    response = wrapped_callback(request, *callback_args, **callback_kwargs)
  File "/home/ubuntu/.pyenv/versions/3.6.10/lib/python3.6/site-packages/django/views/decorators/csrf.py", line 54, in wrapped_view
    return view_func(*args, **kwargs)
  File "/home/ubuntu/.pyenv/versions/3.6.10/lib/python3.6/site-packages/rest_framework/viewsets.py", line 114, in view
    return self.dispatch(request, *args, **kwargs)
  File "/home/ubuntu/.pyenv/versions/3.6.10/lib/python3.6/site-packages/rest_framework/views.py", line 505, in dispatch
    response = self.handle_exception(exc)
  File "/home/ubuntu/.pyenv/versions/3.6.10/lib/python3.6/site-packages/rest_framework/views.py", line 465, in handle_exception
    self.raise_uncaught_exception(exc)
  File "/home/ubuntu/.pyenv/versions/3.6.10/lib/python3.6/site-packages/rest_framework/views.py", line 476, in raise_uncaught_exception
    raise exc
  File "/home/ubuntu/.pyenv/versions/3.6.10/lib/python3.6/site-packages/rest_framework/views.py", line 502, in dispatch
    response = handler(request, *args, **kwargs)
  File "/home/ubuntu/.pyenv/versions/3.6.10/lib/python3.6/site-packages/rest_framework/mixins.py", line 40, in list
    page = self.paginate_queryset(queryset)
  File "/home/ubuntu/.pyenv/versions/3.6.10/lib/python3.6/site-packages/rest_framework/generics.py", line 171, in paginate_queryset
    return self.paginator.paginate_queryset(queryset, self.request, view=self)
  File "/home/ubuntu/.pyenv/versions/3.6.10/lib/python3.6/site-packages/rest_framework/pagination.py", line 218, in paginate_queryset
    return list(self.page)
  File "/home/ubuntu/.pyenv/versions/3.6.10/lib/python3.6/site-packages/django/core/paginator.py", line 150, in __len__
    return len(self.object_list)
  File "/home/ubuntu/.pyenv/versions/3.6.10/lib/python3.6/site-packages/django/db/models/query.py", line 258, in __len__
    self._fetch_all()
  File "/home/ubuntu/.pyenv/versions/3.6.10/lib/python3.6/site-packages/django/db/models/query.py", line 1261, in _fetch_all
    self._result_cache = list(self._iterable_class(self))
  File "/home/ubuntu/.pyenv/versions/3.6.10/lib/python3.6/site-packages/django/db/models/query.py", line 57, in __iter__
    results = compiler.execute_sql(chunked_fetch=self.chunked_fetch, chunk_size=self.chunk_size)
  File "/home/ubuntu/.pyenv/versions/3.6.10/lib/python3.6/site-packages/django/db/models/sql/compiler.py", line 1137, in execute_sql
    cursor.execute(sql, params)
  File "/home/ubuntu/.pyenv/versions/3.6.10/lib/python3.6/site-packages/django/db/backends/utils.py", line 100, in execute
    return super().execute(sql, params)
  File "/home/ubuntu/.pyenv/versions/3.6.10/lib/python3.6/site-packages/django/db/backends/utils.py", line 68, in execute
    return self._execute_with_wrappers(sql, params, many=False, executor=self._execute)
  File "/home/ubuntu/.pyenv/versions/3.6.10/lib/python3.6/site-packages/django/db/backends/utils.py", line 77, in _execute_with_wrappers
    return executor(sql, params, many, context)
  File "/home/ubuntu/.pyenv/versions/3.6.10/lib/python3.6/site-packages/django/db/backends/utils.py", line 86, in _execute
    return self.cursor.execute(sql, params)
  File "/home/ubuntu/.pyenv/versions/3.6.10/lib/python3.6/site-packages/django/db/utils.py", line 90, in __exit__
    raise dj_exc_value.with_traceback(traceback) from exc_value
  File "/home/ubuntu/.pyenv/versions/3.6.10/lib/python3.6/site-packages/django/db/backends/utils.py", line 86, in _execute
    return self.cursor.execute(sql, params)
  File "/home/ubuntu/.pyenv/versions/3.6.10/lib/python3.6/site-packages/django/db/backends/mysql/base.py", line 74, in execute
    return self.cursor.execute(query, args)
  File "/home/ubuntu/.pyenv/versions/3.6.10/lib/python3.6/site-packages/pymysql/cursors.py", line 163, in execute
    result = self._query(query)
  File "/home/ubuntu/.pyenv/versions/3.6.10/lib/python3.6/site-packages/pymysql/cursors.py", line 321, in _query
    conn.query(q)
  File "/home/ubuntu/.pyenv/versions/3.6.10/lib/python3.6/site-packages/pymysql/connections.py", line 505, in query
    self._affected_rows = self._read_query_result(unbuffered=unbuffered)
  File "/home/ubuntu/.pyenv/versions/3.6.10/lib/python3.6/site-packages/pymysql/connections.py", line 724, in _read_query_result
    result.read()
  File "/home/ubuntu/.pyenv/versions/3.6.10/lib/python3.6/site-packages/pymysql/connections.py", line 1069, in read
    first_packet = self.connection._read_packet()
  File "/home/ubuntu/.pyenv/versions/3.6.10/lib/python3.6/site-packages/pymysql/connections.py", line 676, in _read_packet
    packet.raise_for_error()
  File "/home/ubuntu/.pyenv/versions/3.6.10/lib/python3.6/site-packages/pymysql/protocol.py", line 223, in raise_for_error
    err.raise_mysql_exception(self._data)
  File "/home/ubuntu/.pyenv/versions/3.6.10/lib/python3.6/site-packages/pymysql/err.py", line 107, in raise_mysql_exception
    raise errorclass(errno, errval)
django.db.utils.OperationalError: (1054, "Unknown column 'FACILITY_TB.CONTACT_NUMBER' in 'field list'")
[01/Sep/2020 17:26:25] ERROR [django.request:228] Internal Server Error: /facility/
Traceback (most recent call last):
  File "/home/ubuntu/.pyenv/versions/3.6.10/lib/python3.6/site-packages/django/core/handlers/exception.py", line 34, in inner
    response = get_response(request)
  File "/home/ubuntu/.pyenv/versions/3.6.10/lib/python3.6/site-packages/django/core/handlers/base.py", line 115, in _get_response
    response = self.process_exception_by_middleware(e, request)
  File "/home/ubuntu/.pyenv/versions/3.6.10/lib/python3.6/site-packages/django/core/handlers/base.py", line 113, in _get_response
    response = wrapped_callback(request, *callback_args, **callback_kwargs)
  File "/home/ubuntu/.pyenv/versions/3.6.10/lib/python3.6/site-packages/django/views/decorators/csrf.py", line 54, in wrapped_view
    return view_func(*args, **kwargs)
  File "/home/ubuntu/.pyenv/versions/3.6.10/lib/python3.6/site-packages/rest_framework/viewsets.py", line 114, in view
    return self.dispatch(request, *args, **kwargs)
  File "/home/ubuntu/.pyenv/versions/3.6.10/lib/python3.6/site-packages/rest_framework/views.py", line 505, in dispatch
    response = self.handle_exception(exc)
  File "/home/ubuntu/.pyenv/versions/3.6.10/lib/python3.6/site-packages/rest_framework/views.py", line 465, in handle_exception
    self.raise_uncaught_exception(exc)
  File "/home/ubuntu/.pyenv/versions/3.6.10/lib/python3.6/site-packages/rest_framework/views.py", line 476, in raise_uncaught_exception
    raise exc
  File "/home/ubuntu/.pyenv/versions/3.6.10/lib/python3.6/site-packages/rest_framework/views.py", line 502, in dispatch
    response = handler(request, *args, **kwargs)
  File "/home/ubuntu/.pyenv/versions/3.6.10/lib/python3.6/site-packages/rest_framework/mixins.py", line 38, in list
    queryset = self.filter_queryset(self.get_queryset())
  File "/home/ubuntu/.pyenv/versions/3.6.10/lib/python3.6/site-packages/rest_framework/generics.py", line 150, in filter_queryset
    queryset = backend().filter_queryset(self.request, queryset, self)
  File "/home/ubuntu/.pyenv/versions/3.6.10/lib/python3.6/site-packages/rest_framework/filters.py", line 121, in filter_queryset
    queryset = queryset.filter(reduce(operator.and_, conditions))
  File "/home/ubuntu/.pyenv/versions/3.6.10/lib/python3.6/site-packages/django/db/models/query.py", line 904, in filter
    return self._filter_or_exclude(False, *args, **kwargs)
  File "/home/ubuntu/.pyenv/versions/3.6.10/lib/python3.6/site-packages/django/db/models/query.py", line 923, in _filter_or_exclude
    clone.query.add_q(Q(*args, **kwargs))
  File "/home/ubuntu/.pyenv/versions/3.6.10/lib/python3.6/site-packages/django/db/models/sql/query.py", line 1337, in add_q
    clause, _ = self._add_q(q_object, self.used_aliases)
  File "/home/ubuntu/.pyenv/versions/3.6.10/lib/python3.6/site-packages/django/db/models/sql/query.py", line 1359, in _add_q
    current_negated, allow_joins, split_subq, simple_col)
  File "/home/ubuntu/.pyenv/versions/3.6.10/lib/python3.6/site-packages/django/db/models/sql/query.py", line 1365, in _add_q
    split_subq=split_subq, simple_col=simple_col,
  File "/home/ubuntu/.pyenv/versions/3.6.10/lib/python3.6/site-packages/django/db/models/sql/query.py", line 1239, in build_filter
    lookups, parts, reffed_expression = self.solve_lookup_type(arg)
  File "/home/ubuntu/.pyenv/versions/3.6.10/lib/python3.6/site-packages/django/db/models/sql/query.py", line 1077, in solve_lookup_type
    _, field, _, lookup_parts = self.names_to_path(lookup_splitted, self.get_meta())
  File "/home/ubuntu/.pyenv/versions/3.6.10/lib/python3.6/site-packages/django/db/models/sql/query.py", line 1467, in names_to_path
    "Choices are: %s" % (name, ", ".join(available)))
django.core.exceptions.FieldError: Cannot resolve keyword 'facility_type_cd' into field. Choices are: address, contact_number, contents, end_date, facility_id, facilityauthtb, main_img_url, main_type_cd, member, member_id, memberfacilitytb, mod_dt, name, reg_dt, start_date, state_cd, sub_img_url, sub_type_cd, subjecttb, support_tag, title, use
[01/Sep/2020 17:59:51] ERROR [django.request:228] Internal Server Error: /facility/
Traceback (most recent call last):
  File "/home/ubuntu/.pyenv/versions/3.6.10/lib/python3.6/site-packages/django/core/handlers/exception.py", line 34, in inner
    response = get_response(request)
  File "/home/ubuntu/.pyenv/versions/3.6.10/lib/python3.6/site-packages/django/core/handlers/base.py", line 115, in _get_response
    response = self.process_exception_by_middleware(e, request)
  File "/home/ubuntu/.pyenv/versions/3.6.10/lib/python3.6/site-packages/django/core/handlers/base.py", line 113, in _get_response
    response = wrapped_callback(request, *callback_args, **callback_kwargs)
  File "/home/ubuntu/.pyenv/versions/3.6.10/lib/python3.6/site-packages/django/views/decorators/csrf.py", line 54, in wrapped_view
    return view_func(*args, **kwargs)
  File "/home/ubuntu/.pyenv/versions/3.6.10/lib/python3.6/site-packages/rest_framework/viewsets.py", line 114, in view
    return self.dispatch(request, *args, **kwargs)
  File "/home/ubuntu/.pyenv/versions/3.6.10/lib/python3.6/site-packages/rest_framework/views.py", line 505, in dispatch
    response = self.handle_exception(exc)
  File "/home/ubuntu/.pyenv/versions/3.6.10/lib/python3.6/site-packages/rest_framework/views.py", line 465, in handle_exception
    self.raise_uncaught_exception(exc)
  File "/home/ubuntu/.pyenv/versions/3.6.10/lib/python3.6/site-packages/rest_framework/views.py", line 476, in raise_uncaught_exception
    raise exc
  File "/home/ubuntu/.pyenv/versions/3.6.10/lib/python3.6/site-packages/rest_framework/views.py", line 502, in dispatch
    response = handler(request, *args, **kwargs)
  File "/home/ubuntu/.pyenv/versions/3.6.10/lib/python3.6/site-packages/rest_framework/mixins.py", line 38, in list
    queryset = self.filter_queryset(self.get_queryset())
  File "/home/ubuntu/.pyenv/versions/3.6.10/lib/python3.6/site-packages/rest_framework/generics.py", line 150, in filter_queryset
    queryset = backend().filter_queryset(self.request, queryset, self)
  File "/home/ubuntu/.pyenv/versions/3.6.10/lib/python3.6/site-packages/rest_framework/filters.py", line 121, in filter_queryset
    queryset = queryset.filter(reduce(operator.and_, conditions))
  File "/home/ubuntu/.pyenv/versions/3.6.10/lib/python3.6/site-packages/django/db/models/query.py", line 904, in filter
    return self._filter_or_exclude(False, *args, **kwargs)
  File "/home/ubuntu/.pyenv/versions/3.6.10/lib/python3.6/site-packages/django/db/models/query.py", line 923, in _filter_or_exclude
    clone.query.add_q(Q(*args, **kwargs))
  File "/home/ubuntu/.pyenv/versions/3.6.10/lib/python3.6/site-packages/django/db/models/sql/query.py", line 1337, in add_q
    clause, _ = self._add_q(q_object, self.used_aliases)
  File "/home/ubuntu/.pyenv/versions/3.6.10/lib/python3.6/site-packages/django/db/models/sql/query.py", line 1359, in _add_q
    current_negated, allow_joins, split_subq, simple_col)
  File "/home/ubuntu/.pyenv/versions/3.6.10/lib/python3.6/site-packages/django/db/models/sql/query.py", line 1365, in _add_q
    split_subq=split_subq, simple_col=simple_col,
  File "/home/ubuntu/.pyenv/versions/3.6.10/lib/python3.6/site-packages/django/db/models/sql/query.py", line 1239, in build_filter
    lookups, parts, reffed_expression = self.solve_lookup_type(arg)
  File "/home/ubuntu/.pyenv/versions/3.6.10/lib/python3.6/site-packages/django/db/models/sql/query.py", line 1077, in solve_lookup_type
    _, field, _, lookup_parts = self.names_to_path(lookup_splitted, self.get_meta())
  File "/home/ubuntu/.pyenv/versions/3.6.10/lib/python3.6/site-packages/django/db/models/sql/query.py", line 1467, in names_to_path
    "Choices are: %s" % (name, ", ".join(available)))
django.core.exceptions.FieldError: Cannot resolve keyword 'facility_type_cd' into field. Choices are: address, contact_number, contents, end_date, facility_id, facilityauthtb, main_img_url, main_type_cd, member, member_id, memberfacilitytb, mod_dt, name, reg_dt, start_date, state_cd, sub_img_url, sub_type_cd, subjecttb, support_tag, title, use
[01/Sep/2020 17:59:59] ERROR [django.request:228] Internal Server Error: /facility/
Traceback (most recent call last):
  File "/home/ubuntu/.pyenv/versions/3.6.10/lib/python3.6/site-packages/django/core/handlers/exception.py", line 34, in inner
    response = get_response(request)
  File "/home/ubuntu/.pyenv/versions/3.6.10/lib/python3.6/site-packages/django/core/handlers/base.py", line 115, in _get_response
    response = self.process_exception_by_middleware(e, request)
  File "/home/ubuntu/.pyenv/versions/3.6.10/lib/python3.6/site-packages/django/core/handlers/base.py", line 113, in _get_response
    response = wrapped_callback(request, *callback_args, **callback_kwargs)
  File "/home/ubuntu/.pyenv/versions/3.6.10/lib/python3.6/site-packages/django/views/decorators/csrf.py", line 54, in wrapped_view
    return view_func(*args, **kwargs)
  File "/home/ubuntu/.pyenv/versions/3.6.10/lib/python3.6/site-packages/rest_framework/viewsets.py", line 114, in view
    return self.dispatch(request, *args, **kwargs)
  File "/home/ubuntu/.pyenv/versions/3.6.10/lib/python3.6/site-packages/rest_framework/views.py", line 505, in dispatch
    response = self.handle_exception(exc)
  File "/home/ubuntu/.pyenv/versions/3.6.10/lib/python3.6/site-packages/rest_framework/views.py", line 465, in handle_exception
    self.raise_uncaught_exception(exc)
  File "/home/ubuntu/.pyenv/versions/3.6.10/lib/python3.6/site-packages/rest_framework/views.py", line 476, in raise_uncaught_exception
    raise exc
  File "/home/ubuntu/.pyenv/versions/3.6.10/lib/python3.6/site-packages/rest_framework/views.py", line 502, in dispatch
    response = handler(request, *args, **kwargs)
  File "/home/ubuntu/.pyenv/versions/3.6.10/lib/python3.6/site-packages/rest_framework/mixins.py", line 38, in list
    queryset = self.filter_queryset(self.get_queryset())
  File "/home/ubuntu/.pyenv/versions/3.6.10/lib/python3.6/site-packages/rest_framework/generics.py", line 150, in filter_queryset
    queryset = backend().filter_queryset(self.request, queryset, self)
  File "/home/ubuntu/.pyenv/versions/3.6.10/lib/python3.6/site-packages/rest_framework/filters.py", line 121, in filter_queryset
    queryset = queryset.filter(reduce(operator.and_, conditions))
  File "/home/ubuntu/.pyenv/versions/3.6.10/lib/python3.6/site-packages/django/db/models/query.py", line 904, in filter
    return self._filter_or_exclude(False, *args, **kwargs)
  File "/home/ubuntu/.pyenv/versions/3.6.10/lib/python3.6/site-packages/django/db/models/query.py", line 923, in _filter_or_exclude
    clone.query.add_q(Q(*args, **kwargs))
  File "/home/ubuntu/.pyenv/versions/3.6.10/lib/python3.6/site-packages/django/db/models/sql/query.py", line 1337, in add_q
    clause, _ = self._add_q(q_object, self.used_aliases)
  File "/home/ubuntu/.pyenv/versions/3.6.10/lib/python3.6/site-packages/django/db/models/sql/query.py", line 1359, in _add_q
    current_negated, allow_joins, split_subq, simple_col)
  File "/home/ubuntu/.pyenv/versions/3.6.10/lib/python3.6/site-packages/django/db/models/sql/query.py", line 1365, in _add_q
    split_subq=split_subq, simple_col=simple_col,
  File "/home/ubuntu/.pyenv/versions/3.6.10/lib/python3.6/site-packages/django/db/models/sql/query.py", line 1239, in build_filter
    lookups, parts, reffed_expression = self.solve_lookup_type(arg)
  File "/home/ubuntu/.pyenv/versions/3.6.10/lib/python3.6/site-packages/django/db/models/sql/query.py", line 1077, in solve_lookup_type
    _, field, _, lookup_parts = self.names_to_path(lookup_splitted, self.get_meta())
  File "/home/ubuntu/.pyenv/versions/3.6.10/lib/python3.6/site-packages/django/db/models/sql/query.py", line 1467, in names_to_path
    "Choices are: %s" % (name, ", ".join(available)))
django.core.exceptions.FieldError: Cannot resolve keyword 'facility_type_cd' into field. Choices are: address, contact_number, contents, end_date, facility_id, facilityauthtb, main_img_url, main_type_cd, member, member_id, memberfacilitytb, mod_dt, name, reg_dt, start_date, state_cd, sub_img_url, sub_type_cd, subjecttb, support_tag, title, use
[01/Sep/2020 18:00:10] ERROR [django.request:228] Internal Server Error: /facility/
Traceback (most recent call last):
  File "/home/ubuntu/.pyenv/versions/3.6.10/lib/python3.6/site-packages/django/core/handlers/exception.py", line 34, in inner
    response = get_response(request)
  File "/home/ubuntu/.pyenv/versions/3.6.10/lib/python3.6/site-packages/django/core/handlers/base.py", line 115, in _get_response
    response = self.process_exception_by_middleware(e, request)
  File "/home/ubuntu/.pyenv/versions/3.6.10/lib/python3.6/site-packages/django/core/handlers/base.py", line 113, in _get_response
    response = wrapped_callback(request, *callback_args, **callback_kwargs)
  File "/home/ubuntu/.pyenv/versions/3.6.10/lib/python3.6/site-packages/django/views/decorators/csrf.py", line 54, in wrapped_view
    return view_func(*args, **kwargs)
  File "/home/ubuntu/.pyenv/versions/3.6.10/lib/python3.6/site-packages/rest_framework/viewsets.py", line 114, in view
    return self.dispatch(request, *args, **kwargs)
  File "/home/ubuntu/.pyenv/versions/3.6.10/lib/python3.6/site-packages/rest_framework/views.py", line 505, in dispatch
    response = self.handle_exception(exc)
  File "/home/ubuntu/.pyenv/versions/3.6.10/lib/python3.6/site-packages/rest_framework/views.py", line 465, in handle_exception
    self.raise_uncaught_exception(exc)
  File "/home/ubuntu/.pyenv/versions/3.6.10/lib/python3.6/site-packages/rest_framework/views.py", line 476, in raise_uncaught_exception
    raise exc
  File "/home/ubuntu/.pyenv/versions/3.6.10/lib/python3.6/site-packages/rest_framework/views.py", line 502, in dispatch
    response = handler(request, *args, **kwargs)
  File "/home/ubuntu/.pyenv/versions/3.6.10/lib/python3.6/site-packages/rest_framework/mixins.py", line 38, in list
    queryset = self.filter_queryset(self.get_queryset())
  File "/home/ubuntu/.pyenv/versions/3.6.10/lib/python3.6/site-packages/rest_framework/generics.py", line 150, in filter_queryset
    queryset = backend().filter_queryset(self.request, queryset, self)
  File "/home/ubuntu/.pyenv/versions/3.6.10/lib/python3.6/site-packages/rest_framework/filters.py", line 121, in filter_queryset
    queryset = queryset.filter(reduce(operator.and_, conditions))
  File "/home/ubuntu/.pyenv/versions/3.6.10/lib/python3.6/site-packages/django/db/models/query.py", line 904, in filter
    return self._filter_or_exclude(False, *args, **kwargs)
  File "/home/ubuntu/.pyenv/versions/3.6.10/lib/python3.6/site-packages/django/db/models/query.py", line 923, in _filter_or_exclude
    clone.query.add_q(Q(*args, **kwargs))
  File "/home/ubuntu/.pyenv/versions/3.6.10/lib/python3.6/site-packages/django/db/models/sql/query.py", line 1337, in add_q
    clause, _ = self._add_q(q_object, self.used_aliases)
  File "/home/ubuntu/.pyenv/versions/3.6.10/lib/python3.6/site-packages/django/db/models/sql/query.py", line 1359, in _add_q
    current_negated, allow_joins, split_subq, simple_col)
  File "/home/ubuntu/.pyenv/versions/3.6.10/lib/python3.6/site-packages/django/db/models/sql/query.py", line 1365, in _add_q
    split_subq=split_subq, simple_col=simple_col,
  File "/home/ubuntu/.pyenv/versions/3.6.10/lib/python3.6/site-packages/django/db/models/sql/query.py", line 1239, in build_filter
    lookups, parts, reffed_expression = self.solve_lookup_type(arg)
  File "/home/ubuntu/.pyenv/versions/3.6.10/lib/python3.6/site-packages/django/db/models/sql/query.py", line 1077, in solve_lookup_type
    _, field, _, lookup_parts = self.names_to_path(lookup_splitted, self.get_meta())
  File "/home/ubuntu/.pyenv/versions/3.6.10/lib/python3.6/site-packages/django/db/models/sql/query.py", line 1467, in names_to_path
    "Choices are: %s" % (name, ", ".join(available)))
django.core.exceptions.FieldError: Cannot resolve keyword 'facility_type_cd' into field. Choices are: address, contact_number, contents, end_date, facility_id, facilityauthtb, main_img_url, main_type_cd, member, member_id, memberfacilitytb, mod_dt, name, reg_dt, start_date, state_cd, sub_img_url, sub_type_cd, subjecttb, support_tag, title, use
[01/Sep/2020 18:00:13] ERROR [django.request:228] Internal Server Error: /facility/
Traceback (most recent call last):
  File "/home/ubuntu/.pyenv/versions/3.6.10/lib/python3.6/site-packages/django/core/handlers/exception.py", line 34, in inner
    response = get_response(request)
  File "/home/ubuntu/.pyenv/versions/3.6.10/lib/python3.6/site-packages/django/core/handlers/base.py", line 115, in _get_response
    response = self.process_exception_by_middleware(e, request)
  File "/home/ubuntu/.pyenv/versions/3.6.10/lib/python3.6/site-packages/django/core/handlers/base.py", line 113, in _get_response
    response = wrapped_callback(request, *callback_args, **callback_kwargs)
  File "/home/ubuntu/.pyenv/versions/3.6.10/lib/python3.6/site-packages/django/views/decorators/csrf.py", line 54, in wrapped_view
    return view_func(*args, **kwargs)
  File "/home/ubuntu/.pyenv/versions/3.6.10/lib/python3.6/site-packages/rest_framework/viewsets.py", line 114, in view
    return self.dispatch(request, *args, **kwargs)
  File "/home/ubuntu/.pyenv/versions/3.6.10/lib/python3.6/site-packages/rest_framework/views.py", line 505, in dispatch
    response = self.handle_exception(exc)
  File "/home/ubuntu/.pyenv/versions/3.6.10/lib/python3.6/site-packages/rest_framework/views.py", line 465, in handle_exception
    self.raise_uncaught_exception(exc)
  File "/home/ubuntu/.pyenv/versions/3.6.10/lib/python3.6/site-packages/rest_framework/views.py", line 476, in raise_uncaught_exception
    raise exc
  File "/home/ubuntu/.pyenv/versions/3.6.10/lib/python3.6/site-packages/rest_framework/views.py", line 502, in dispatch
    response = handler(request, *args, **kwargs)
  File "/home/ubuntu/.pyenv/versions/3.6.10/lib/python3.6/site-packages/rest_framework/mixins.py", line 38, in list
    queryset = self.filter_queryset(self.get_queryset())
  File "/home/ubuntu/.pyenv/versions/3.6.10/lib/python3.6/site-packages/rest_framework/generics.py", line 150, in filter_queryset
    queryset = backend().filter_queryset(self.request, queryset, self)
  File "/home/ubuntu/.pyenv/versions/3.6.10/lib/python3.6/site-packages/rest_framework/filters.py", line 121, in filter_queryset
    queryset = queryset.filter(reduce(operator.and_, conditions))
  File "/home/ubuntu/.pyenv/versions/3.6.10/lib/python3.6/site-packages/django/db/models/query.py", line 904, in filter
    return self._filter_or_exclude(False, *args, **kwargs)
  File "/home/ubuntu/.pyenv/versions/3.6.10/lib/python3.6/site-packages/django/db/models/query.py", line 923, in _filter_or_exclude
    clone.query.add_q(Q(*args, **kwargs))
  File "/home/ubuntu/.pyenv/versions/3.6.10/lib/python3.6/site-packages/django/db/models/sql/query.py", line 1337, in add_q
    clause, _ = self._add_q(q_object, self.used_aliases)
  File "/home/ubuntu/.pyenv/versions/3.6.10/lib/python3.6/site-packages/django/db/models/sql/query.py", line 1359, in _add_q
    current_negated, allow_joins, split_subq, simple_col)
  File "/home/ubuntu/.pyenv/versions/3.6.10/lib/python3.6/site-packages/django/db/models/sql/query.py", line 1365, in _add_q
    split_subq=split_subq, simple_col=simple_col,
  File "/home/ubuntu/.pyenv/versions/3.6.10/lib/python3.6/site-packages/django/db/models/sql/query.py", line 1239, in build_filter
    lookups, parts, reffed_expression = self.solve_lookup_type(arg)
  File "/home/ubuntu/.pyenv/versions/3.6.10/lib/python3.6/site-packages/django/db/models/sql/query.py", line 1077, in solve_lookup_type
    _, field, _, lookup_parts = self.names_to_path(lookup_splitted, self.get_meta())
  File "/home/ubuntu/.pyenv/versions/3.6.10/lib/python3.6/site-packages/django/db/models/sql/query.py", line 1467, in names_to_path
    "Choices are: %s" % (name, ", ".join(available)))
django.core.exceptions.FieldError: Cannot resolve keyword 'facility_type_cd' into field. Choices are: address, contact_number, contents, end_date, facility_id, facilityauthtb, main_img_url, main_type_cd, member, member_id, memberfacilitytb, mod_dt, name, reg_dt, start_date, state_cd, sub_img_url, sub_type_cd, subjecttb, support_tag, title, use
[01/Sep/2020 18:00:46] ERROR [django.request:228] Internal Server Error: /facility/
Traceback (most recent call last):
  File "/home/ubuntu/.pyenv/versions/3.6.10/lib/python3.6/site-packages/django/core/handlers/exception.py", line 34, in inner
    response = get_response(request)
  File "/home/ubuntu/.pyenv/versions/3.6.10/lib/python3.6/site-packages/django/core/handlers/base.py", line 115, in _get_response
    response = self.process_exception_by_middleware(e, request)
  File "/home/ubuntu/.pyenv/versions/3.6.10/lib/python3.6/site-packages/django/core/handlers/base.py", line 113, in _get_response
    response = wrapped_callback(request, *callback_args, **callback_kwargs)
  File "/home/ubuntu/.pyenv/versions/3.6.10/lib/python3.6/site-packages/django/views/decorators/csrf.py", line 54, in wrapped_view
    return view_func(*args, **kwargs)
  File "/home/ubuntu/.pyenv/versions/3.6.10/lib/python3.6/site-packages/rest_framework/viewsets.py", line 114, in view
    return self.dispatch(request, *args, **kwargs)
  File "/home/ubuntu/.pyenv/versions/3.6.10/lib/python3.6/site-packages/rest_framework/views.py", line 505, in dispatch
    response = self.handle_exception(exc)
  File "/home/ubuntu/.pyenv/versions/3.6.10/lib/python3.6/site-packages/rest_framework/views.py", line 465, in handle_exception
    self.raise_uncaught_exception(exc)
  File "/home/ubuntu/.pyenv/versions/3.6.10/lib/python3.6/site-packages/rest_framework/views.py", line 476, in raise_uncaught_exception
    raise exc
  File "/home/ubuntu/.pyenv/versions/3.6.10/lib/python3.6/site-packages/rest_framework/views.py", line 502, in dispatch
    response = handler(request, *args, **kwargs)
  File "/home/ubuntu/.pyenv/versions/3.6.10/lib/python3.6/site-packages/rest_framework/mixins.py", line 38, in list
    queryset = self.filter_queryset(self.get_queryset())
  File "/home/ubuntu/.pyenv/versions/3.6.10/lib/python3.6/site-packages/rest_framework/generics.py", line 150, in filter_queryset
    queryset = backend().filter_queryset(self.request, queryset, self)
  File "/home/ubuntu/.pyenv/versions/3.6.10/lib/python3.6/site-packages/rest_framework/filters.py", line 121, in filter_queryset
    queryset = queryset.filter(reduce(operator.and_, conditions))
  File "/home/ubuntu/.pyenv/versions/3.6.10/lib/python3.6/site-packages/django/db/models/query.py", line 904, in filter
    return self._filter_or_exclude(False, *args, **kwargs)
  File "/home/ubuntu/.pyenv/versions/3.6.10/lib/python3.6/site-packages/django/db/models/query.py", line 923, in _filter_or_exclude
    clone.query.add_q(Q(*args, **kwargs))
  File "/home/ubuntu/.pyenv/versions/3.6.10/lib/python3.6/site-packages/django/db/models/sql/query.py", line 1337, in add_q
    clause, _ = self._add_q(q_object, self.used_aliases)
  File "/home/ubuntu/.pyenv/versions/3.6.10/lib/python3.6/site-packages/django/db/models/sql/query.py", line 1359, in _add_q
    current_negated, allow_joins, split_subq, simple_col)
  File "/home/ubuntu/.pyenv/versions/3.6.10/lib/python3.6/site-packages/django/db/models/sql/query.py", line 1365, in _add_q
    split_subq=split_subq, simple_col=simple_col,
  File "/home/ubuntu/.pyenv/versions/3.6.10/lib/python3.6/site-packages/django/db/models/sql/query.py", line 1239, in build_filter
    lookups, parts, reffed_expression = self.solve_lookup_type(arg)
  File "/home/ubuntu/.pyenv/versions/3.6.10/lib/python3.6/site-packages/django/db/models/sql/query.py", line 1077, in solve_lookup_type
    _, field, _, lookup_parts = self.names_to_path(lookup_splitted, self.get_meta())
  File "/home/ubuntu/.pyenv/versions/3.6.10/lib/python3.6/site-packages/django/db/models/sql/query.py", line 1467, in names_to_path
    "Choices are: %s" % (name, ", ".join(available)))
django.core.exceptions.FieldError: Cannot resolve keyword 'facility_type_cd' into field. Choices are: address, contact_number, contents, end_date, facility_id, facilityauthtb, main_img_url, main_type_cd, member, member_id, memberfacilitytb, mod_dt, name, reg_dt, start_date, state_cd, sub_img_url, sub_type_cd, subjecttb, support_tag, title, use
[01/Sep/2020 18:00:49] ERROR [django.request:228] Internal Server Error: /facility/
Traceback (most recent call last):
  File "/home/ubuntu/.pyenv/versions/3.6.10/lib/python3.6/site-packages/django/core/handlers/exception.py", line 34, in inner
    response = get_response(request)
  File "/home/ubuntu/.pyenv/versions/3.6.10/lib/python3.6/site-packages/django/core/handlers/base.py", line 115, in _get_response
    response = self.process_exception_by_middleware(e, request)
  File "/home/ubuntu/.pyenv/versions/3.6.10/lib/python3.6/site-packages/django/core/handlers/base.py", line 113, in _get_response
    response = wrapped_callback(request, *callback_args, **callback_kwargs)
  File "/home/ubuntu/.pyenv/versions/3.6.10/lib/python3.6/site-packages/django/views/decorators/csrf.py", line 54, in wrapped_view
    return view_func(*args, **kwargs)
  File "/home/ubuntu/.pyenv/versions/3.6.10/lib/python3.6/site-packages/rest_framework/viewsets.py", line 114, in view
    return self.dispatch(request, *args, **kwargs)
  File "/home/ubuntu/.pyenv/versions/3.6.10/lib/python3.6/site-packages/rest_framework/views.py", line 505, in dispatch
    response = self.handle_exception(exc)
  File "/home/ubuntu/.pyenv/versions/3.6.10/lib/python3.6/site-packages/rest_framework/views.py", line 465, in handle_exception
    self.raise_uncaught_exception(exc)
  File "/home/ubuntu/.pyenv/versions/3.6.10/lib/python3.6/site-packages/rest_framework/views.py", line 476, in raise_uncaught_exception
    raise exc
  File "/home/ubuntu/.pyenv/versions/3.6.10/lib/python3.6/site-packages/rest_framework/views.py", line 502, in dispatch
    response = handler(request, *args, **kwargs)
  File "/home/ubuntu/.pyenv/versions/3.6.10/lib/python3.6/site-packages/rest_framework/mixins.py", line 38, in list
    queryset = self.filter_queryset(self.get_queryset())
  File "/home/ubuntu/.pyenv/versions/3.6.10/lib/python3.6/site-packages/rest_framework/generics.py", line 150, in filter_queryset
    queryset = backend().filter_queryset(self.request, queryset, self)
  File "/home/ubuntu/.pyenv/versions/3.6.10/lib/python3.6/site-packages/rest_framework/filters.py", line 121, in filter_queryset
    queryset = queryset.filter(reduce(operator.and_, conditions))
  File "/home/ubuntu/.pyenv/versions/3.6.10/lib/python3.6/site-packages/django/db/models/query.py", line 904, in filter
    return self._filter_or_exclude(False, *args, **kwargs)
  File "/home/ubuntu/.pyenv/versions/3.6.10/lib/python3.6/site-packages/django/db/models/query.py", line 923, in _filter_or_exclude
    clone.query.add_q(Q(*args, **kwargs))
  File "/home/ubuntu/.pyenv/versions/3.6.10/lib/python3.6/site-packages/django/db/models/sql/query.py", line 1337, in add_q
    clause, _ = self._add_q(q_object, self.used_aliases)
  File "/home/ubuntu/.pyenv/versions/3.6.10/lib/python3.6/site-packages/django/db/models/sql/query.py", line 1359, in _add_q
    current_negated, allow_joins, split_subq, simple_col)
  File "/home/ubuntu/.pyenv/versions/3.6.10/lib/python3.6/site-packages/django/db/models/sql/query.py", line 1365, in _add_q
    split_subq=split_subq, simple_col=simple_col,
  File "/home/ubuntu/.pyenv/versions/3.6.10/lib/python3.6/site-packages/django/db/models/sql/query.py", line 1239, in build_filter
    lookups, parts, reffed_expression = self.solve_lookup_type(arg)
  File "/home/ubuntu/.pyenv/versions/3.6.10/lib/python3.6/site-packages/django/db/models/sql/query.py", line 1077, in solve_lookup_type
    _, field, _, lookup_parts = self.names_to_path(lookup_splitted, self.get_meta())
  File "/home/ubuntu/.pyenv/versions/3.6.10/lib/python3.6/site-packages/django/db/models/sql/query.py", line 1467, in names_to_path
    "Choices are: %s" % (name, ", ".join(available)))
django.core.exceptions.FieldError: Cannot resolve keyword 'facility_type_cd' into field. Choices are: address, contact_number, contents, end_date, facility_id, facilityauthtb, main_img_url, main_type_cd, member, member_id, memberfacilitytb, mod_dt, name, reg_dt, start_date, state_cd, sub_img_url, sub_type_cd, subjecttb, support_tag, title, use
[01/Sep/2020 18:01:10] ERROR [django.request:228] Internal Server Error: /facility/
Traceback (most recent call last):
  File "/home/ubuntu/.pyenv/versions/3.6.10/lib/python3.6/site-packages/django/core/handlers/exception.py", line 34, in inner
    response = get_response(request)
  File "/home/ubuntu/.pyenv/versions/3.6.10/lib/python3.6/site-packages/django/core/handlers/base.py", line 115, in _get_response
    response = self.process_exception_by_middleware(e, request)
  File "/home/ubuntu/.pyenv/versions/3.6.10/lib/python3.6/site-packages/django/core/handlers/base.py", line 113, in _get_response
    response = wrapped_callback(request, *callback_args, **callback_kwargs)
  File "/home/ubuntu/.pyenv/versions/3.6.10/lib/python3.6/site-packages/django/views/decorators/csrf.py", line 54, in wrapped_view
    return view_func(*args, **kwargs)
  File "/home/ubuntu/.pyenv/versions/3.6.10/lib/python3.6/site-packages/rest_framework/viewsets.py", line 114, in view
    return self.dispatch(request, *args, **kwargs)
  File "/home/ubuntu/.pyenv/versions/3.6.10/lib/python3.6/site-packages/rest_framework/views.py", line 505, in dispatch
    response = self.handle_exception(exc)
  File "/home/ubuntu/.pyenv/versions/3.6.10/lib/python3.6/site-packages/rest_framework/views.py", line 465, in handle_exception
    self.raise_uncaught_exception(exc)
  File "/home/ubuntu/.pyenv/versions/3.6.10/lib/python3.6/site-packages/rest_framework/views.py", line 476, in raise_uncaught_exception
    raise exc
  File "/home/ubuntu/.pyenv/versions/3.6.10/lib/python3.6/site-packages/rest_framework/views.py", line 502, in dispatch
    response = handler(request, *args, **kwargs)
  File "/home/ubuntu/.pyenv/versions/3.6.10/lib/python3.6/site-packages/rest_framework/mixins.py", line 38, in list
    queryset = self.filter_queryset(self.get_queryset())
  File "/home/ubuntu/.pyenv/versions/3.6.10/lib/python3.6/site-packages/rest_framework/generics.py", line 150, in filter_queryset
    queryset = backend().filter_queryset(self.request, queryset, self)
  File "/home/ubuntu/.pyenv/versions/3.6.10/lib/python3.6/site-packages/rest_framework/filters.py", line 121, in filter_queryset
    queryset = queryset.filter(reduce(operator.and_, conditions))
  File "/home/ubuntu/.pyenv/versions/3.6.10/lib/python3.6/site-packages/django/db/models/query.py", line 904, in filter
    return self._filter_or_exclude(False, *args, **kwargs)
  File "/home/ubuntu/.pyenv/versions/3.6.10/lib/python3.6/site-packages/django/db/models/query.py", line 923, in _filter_or_exclude
    clone.query.add_q(Q(*args, **kwargs))
  File "/home/ubuntu/.pyenv/versions/3.6.10/lib/python3.6/site-packages/django/db/models/sql/query.py", line 1337, in add_q
    clause, _ = self._add_q(q_object, self.used_aliases)
  File "/home/ubuntu/.pyenv/versions/3.6.10/lib/python3.6/site-packages/django/db/models/sql/query.py", line 1359, in _add_q
    current_negated, allow_joins, split_subq, simple_col)
  File "/home/ubuntu/.pyenv/versions/3.6.10/lib/python3.6/site-packages/django/db/models/sql/query.py", line 1365, in _add_q
    split_subq=split_subq, simple_col=simple_col,
  File "/home/ubuntu/.pyenv/versions/3.6.10/lib/python3.6/site-packages/django/db/models/sql/query.py", line 1239, in build_filter
    lookups, parts, reffed_expression = self.solve_lookup_type(arg)
  File "/home/ubuntu/.pyenv/versions/3.6.10/lib/python3.6/site-packages/django/db/models/sql/query.py", line 1077, in solve_lookup_type
    _, field, _, lookup_parts = self.names_to_path(lookup_splitted, self.get_meta())
  File "/home/ubuntu/.pyenv/versions/3.6.10/lib/python3.6/site-packages/django/db/models/sql/query.py", line 1467, in names_to_path
    "Choices are: %s" % (name, ", ".join(available)))
django.core.exceptions.FieldError: Cannot resolve keyword 'facility_type_cd' into field. Choices are: address, contact_number, contents, end_date, facility_id, facilityauthtb, main_img_url, main_type_cd, member, member_id, memberfacilitytb, mod_dt, name, reg_dt, start_date, state_cd, sub_img_url, sub_type_cd, subjecttb, support_tag, title, use
[01/Sep/2020 18:01:54] ERROR [django.request:228] Internal Server Error: /facility/
Traceback (most recent call last):
  File "/home/ubuntu/.pyenv/versions/3.6.10/lib/python3.6/site-packages/django/core/handlers/exception.py", line 34, in inner
    response = get_response(request)
  File "/home/ubuntu/.pyenv/versions/3.6.10/lib/python3.6/site-packages/django/core/handlers/base.py", line 115, in _get_response
    response = self.process_exception_by_middleware(e, request)
  File "/home/ubuntu/.pyenv/versions/3.6.10/lib/python3.6/site-packages/django/core/handlers/base.py", line 113, in _get_response
    response = wrapped_callback(request, *callback_args, **callback_kwargs)
  File "/home/ubuntu/.pyenv/versions/3.6.10/lib/python3.6/site-packages/django/views/decorators/csrf.py", line 54, in wrapped_view
    return view_func(*args, **kwargs)
  File "/home/ubuntu/.pyenv/versions/3.6.10/lib/python3.6/site-packages/rest_framework/viewsets.py", line 114, in view
    return self.dispatch(request, *args, **kwargs)
  File "/home/ubuntu/.pyenv/versions/3.6.10/lib/python3.6/site-packages/rest_framework/views.py", line 505, in dispatch
    response = self.handle_exception(exc)
  File "/home/ubuntu/.pyenv/versions/3.6.10/lib/python3.6/site-packages/rest_framework/views.py", line 465, in handle_exception
    self.raise_uncaught_exception(exc)
  File "/home/ubuntu/.pyenv/versions/3.6.10/lib/python3.6/site-packages/rest_framework/views.py", line 476, in raise_uncaught_exception
    raise exc
  File "/home/ubuntu/.pyenv/versions/3.6.10/lib/python3.6/site-packages/rest_framework/views.py", line 502, in dispatch
    response = handler(request, *args, **kwargs)
  File "/home/ubuntu/.pyenv/versions/3.6.10/lib/python3.6/site-packages/rest_framework/mixins.py", line 38, in list
    queryset = self.filter_queryset(self.get_queryset())
  File "/home/ubuntu/.pyenv/versions/3.6.10/lib/python3.6/site-packages/rest_framework/generics.py", line 150, in filter_queryset
    queryset = backend().filter_queryset(self.request, queryset, self)
  File "/home/ubuntu/.pyenv/versions/3.6.10/lib/python3.6/site-packages/rest_framework/filters.py", line 121, in filter_queryset
    queryset = queryset.filter(reduce(operator.and_, conditions))
  File "/home/ubuntu/.pyenv/versions/3.6.10/lib/python3.6/site-packages/django/db/models/query.py", line 904, in filter
    return self._filter_or_exclude(False, *args, **kwargs)
  File "/home/ubuntu/.pyenv/versions/3.6.10/lib/python3.6/site-packages/django/db/models/query.py", line 923, in _filter_or_exclude
    clone.query.add_q(Q(*args, **kwargs))
  File "/home/ubuntu/.pyenv/versions/3.6.10/lib/python3.6/site-packages/django/db/models/sql/query.py", line 1337, in add_q
    clause, _ = self._add_q(q_object, self.used_aliases)
  File "/home/ubuntu/.pyenv/versions/3.6.10/lib/python3.6/site-packages/django/db/models/sql/query.py", line 1359, in _add_q
    current_negated, allow_joins, split_subq, simple_col)
  File "/home/ubuntu/.pyenv/versions/3.6.10/lib/python3.6/site-packages/django/db/models/sql/query.py", line 1365, in _add_q
    split_subq=split_subq, simple_col=simple_col,
  File "/home/ubuntu/.pyenv/versions/3.6.10/lib/python3.6/site-packages/django/db/models/sql/query.py", line 1239, in build_filter
    lookups, parts, reffed_expression = self.solve_lookup_type(arg)
  File "/home/ubuntu/.pyenv/versions/3.6.10/lib/python3.6/site-packages/django/db/models/sql/query.py", line 1077, in solve_lookup_type
    _, field, _, lookup_parts = self.names_to_path(lookup_splitted, self.get_meta())
  File "/home/ubuntu/.pyenv/versions/3.6.10/lib/python3.6/site-packages/django/db/models/sql/query.py", line 1467, in names_to_path
    "Choices are: %s" % (name, ", ".join(available)))
django.core.exceptions.FieldError: Cannot resolve keyword 'facility_type_cd' into field. Choices are: address, contact_number, contents, end_date, facility_id, facilityauthtb, main_img_url, main_type_cd, member, member_id, memberfacilitytb, mod_dt, name, reg_dt, start_date, state_cd, sub_img_url, sub_type_cd, subjecttb, support_tag, title, use
[01/Sep/2020 18:02:20] ERROR [django.request:228] Internal Server Error: /facility/
Traceback (most recent call last):
  File "/home/ubuntu/.pyenv/versions/3.6.10/lib/python3.6/site-packages/django/core/handlers/exception.py", line 34, in inner
    response = get_response(request)
  File "/home/ubuntu/.pyenv/versions/3.6.10/lib/python3.6/site-packages/django/core/handlers/base.py", line 115, in _get_response
    response = self.process_exception_by_middleware(e, request)
  File "/home/ubuntu/.pyenv/versions/3.6.10/lib/python3.6/site-packages/django/core/handlers/base.py", line 113, in _get_response
    response = wrapped_callback(request, *callback_args, **callback_kwargs)
  File "/home/ubuntu/.pyenv/versions/3.6.10/lib/python3.6/site-packages/django/views/decorators/csrf.py", line 54, in wrapped_view
    return view_func(*args, **kwargs)
  File "/home/ubuntu/.pyenv/versions/3.6.10/lib/python3.6/site-packages/rest_framework/viewsets.py", line 114, in view
    return self.dispatch(request, *args, **kwargs)
  File "/home/ubuntu/.pyenv/versions/3.6.10/lib/python3.6/site-packages/rest_framework/views.py", line 505, in dispatch
    response = self.handle_exception(exc)
  File "/home/ubuntu/.pyenv/versions/3.6.10/lib/python3.6/site-packages/rest_framework/views.py", line 465, in handle_exception
    self.raise_uncaught_exception(exc)
  File "/home/ubuntu/.pyenv/versions/3.6.10/lib/python3.6/site-packages/rest_framework/views.py", line 476, in raise_uncaught_exception
    raise exc
  File "/home/ubuntu/.pyenv/versions/3.6.10/lib/python3.6/site-packages/rest_framework/views.py", line 502, in dispatch
    response = handler(request, *args, **kwargs)
  File "/home/ubuntu/.pyenv/versions/3.6.10/lib/python3.6/site-packages/rest_framework/mixins.py", line 38, in list
    queryset = self.filter_queryset(self.get_queryset())
  File "/home/ubuntu/.pyenv/versions/3.6.10/lib/python3.6/site-packages/rest_framework/generics.py", line 150, in filter_queryset
    queryset = backend().filter_queryset(self.request, queryset, self)
  File "/home/ubuntu/.pyenv/versions/3.6.10/lib/python3.6/site-packages/rest_framework/filters.py", line 121, in filter_queryset
    queryset = queryset.filter(reduce(operator.and_, conditions))
  File "/home/ubuntu/.pyenv/versions/3.6.10/lib/python3.6/site-packages/django/db/models/query.py", line 904, in filter
    return self._filter_or_exclude(False, *args, **kwargs)
  File "/home/ubuntu/.pyenv/versions/3.6.10/lib/python3.6/site-packages/django/db/models/query.py", line 923, in _filter_or_exclude
    clone.query.add_q(Q(*args, **kwargs))
  File "/home/ubuntu/.pyenv/versions/3.6.10/lib/python3.6/site-packages/django/db/models/sql/query.py", line 1337, in add_q
    clause, _ = self._add_q(q_object, self.used_aliases)
  File "/home/ubuntu/.pyenv/versions/3.6.10/lib/python3.6/site-packages/django/db/models/sql/query.py", line 1359, in _add_q
    current_negated, allow_joins, split_subq, simple_col)
  File "/home/ubuntu/.pyenv/versions/3.6.10/lib/python3.6/site-packages/django/db/models/sql/query.py", line 1365, in _add_q
    split_subq=split_subq, simple_col=simple_col,
  File "/home/ubuntu/.pyenv/versions/3.6.10/lib/python3.6/site-packages/django/db/models/sql/query.py", line 1239, in build_filter
    lookups, parts, reffed_expression = self.solve_lookup_type(arg)
  File "/home/ubuntu/.pyenv/versions/3.6.10/lib/python3.6/site-packages/django/db/models/sql/query.py", line 1077, in solve_lookup_type
    _, field, _, lookup_parts = self.names_to_path(lookup_splitted, self.get_meta())
  File "/home/ubuntu/.pyenv/versions/3.6.10/lib/python3.6/site-packages/django/db/models/sql/query.py", line 1467, in names_to_path
    "Choices are: %s" % (name, ", ".join(available)))
django.core.exceptions.FieldError: Cannot resolve keyword 'facility_type_cd' into field. Choices are: address, contact_number, contents, end_date, facility_id, facilityauthtb, main_img_url, main_type_cd, member, member_id, memberfacilitytb, mod_dt, name, reg_dt, start_date, state_cd, sub_img_url, sub_type_cd, subjecttb, support_tag, title, use
=======
[01/Sep/2020 17:27:11] ERROR [django.request:228] Internal Server Error: /facility/
Traceback (most recent call last):
  File "C:\Users\savek\Documents\spooner\project\pters-connect-venv\lib\site-packages\django\core\handlers\exception.py", line 34, in inner
    response = get_response(request)
  File "C:\Users\savek\Documents\spooner\project\pters-connect-venv\lib\site-packages\django\core\handlers\base.py", line 115, in _get_response
    response = self.process_exception_by_middleware(e, request)
  File "C:\Users\savek\Documents\spooner\project\pters-connect-venv\lib\site-packages\django\core\handlers\base.py", line 113, in _get_response
    response = wrapped_callback(request, *callback_args, **callback_kwargs)
  File "C:\Users\savek\Documents\spooner\project\pters-connect-venv\lib\site-packages\django\views\decorators\csrf.py", line 54, in wrapped_view
    return view_func(*args, **kwargs)
  File "C:\Users\savek\Documents\spooner\project\pters-connect-venv\lib\site-packages\rest_framework\viewsets.py", line 114, in view
    return self.dispatch(request, *args, **kwargs)
  File "C:\Users\savek\Documents\spooner\project\pters-connect-venv\lib\site-packages\rest_framework\views.py", line 505, in dispatch
    response = self.handle_exception(exc)
  File "C:\Users\savek\Documents\spooner\project\pters-connect-venv\lib\site-packages\rest_framework\views.py", line 465, in handle_exception
    self.raise_uncaught_exception(exc)
  File "C:\Users\savek\Documents\spooner\project\pters-connect-venv\lib\site-packages\rest_framework\views.py", line 476, in raise_uncaught_exception
    raise exc
  File "C:\Users\savek\Documents\spooner\project\pters-connect-venv\lib\site-packages\rest_framework\views.py", line 502, in dispatch
    response = handler(request, *args, **kwargs)
  File "C:\Users\savek\Documents\spooner\project\pters-connect-venv\lib\site-packages\rest_framework\mixins.py", line 38, in list
    queryset = self.filter_queryset(self.get_queryset())
  File "C:\Users\savek\Documents\spooner\project\pters-connect-venv\lib\site-packages\rest_framework\generics.py", line 150, in filter_queryset
    queryset = backend().filter_queryset(self.request, queryset, self)
  File "C:\Users\savek\Documents\spooner\project\pters-connect-venv\lib\site-packages\rest_framework\filters.py", line 121, in filter_queryset
    queryset = queryset.filter(reduce(operator.and_, conditions))
  File "C:\Users\savek\Documents\spooner\project\pters-connect-venv\lib\site-packages\django\db\models\query.py", line 904, in filter
    return self._filter_or_exclude(False, *args, **kwargs)
  File "C:\Users\savek\Documents\spooner\project\pters-connect-venv\lib\site-packages\django\db\models\query.py", line 923, in _filter_or_exclude
    clone.query.add_q(Q(*args, **kwargs))
  File "C:\Users\savek\Documents\spooner\project\pters-connect-venv\lib\site-packages\django\db\models\sql\query.py", line 1337, in add_q
    clause, _ = self._add_q(q_object, self.used_aliases)
  File "C:\Users\savek\Documents\spooner\project\pters-connect-venv\lib\site-packages\django\db\models\sql\query.py", line 1359, in _add_q
    current_negated, allow_joins, split_subq, simple_col)
  File "C:\Users\savek\Documents\spooner\project\pters-connect-venv\lib\site-packages\django\db\models\sql\query.py", line 1365, in _add_q
    split_subq=split_subq, simple_col=simple_col,
  File "C:\Users\savek\Documents\spooner\project\pters-connect-venv\lib\site-packages\django\db\models\sql\query.py", line 1239, in build_filter
    lookups, parts, reffed_expression = self.solve_lookup_type(arg)
  File "C:\Users\savek\Documents\spooner\project\pters-connect-venv\lib\site-packages\django\db\models\sql\query.py", line 1077, in solve_lookup_type
    _, field, _, lookup_parts = self.names_to_path(lookup_splitted, self.get_meta())
  File "C:\Users\savek\Documents\spooner\project\pters-connect-venv\lib\site-packages\django\db\models\sql\query.py", line 1467, in names_to_path
    "Choices are: %s" % (name, ", ".join(available)))
django.core.exceptions.FieldError: Cannot resolve keyword 'facility_type_cd' into field. Choices are: address, contact_number, contents, end_date, facility_id, facilityauthtb, main_img_url, main_type_cd, member, member_id, memberfacilitytb, mod_dt, name, reg_dt, start_date, state_cd, sub_img_url, sub_type_cd, subjecttb, support_tag, title, use
[01/Sep/2020 17:27:11] ERROR [django.server:157] "GET /facility/?search=12 HTTP/1.1" 500 28467
>>>>>>> d1f52b9cac3c96012449bb4b90a222c81f85a446
